Workbook
Name alpha: #REF!
Name Andeen: #REF!
Name beta: #REF!
Name C_1: #REF!
Name C_standard_uncertainty: #REF!
Name C_unit_mult: #REF!
Name correction_c: #REF!
Name corrections: #REF!
Name Data: #REF!
Name Date: #REF!
Name differentzero: #REF!
Name frequency: #REF!
Name G_1: #REF!
Name G_2: #REF!
Name G_standard_uncertainty: #REF!
Name G_unit_mult: #REF!
Name hist_16: #REF!
Name hist1074: #REF!
Name history: #REF!
Name Inductance: #REF!
Name inductor1: pyUBresults!$A$3:$AI$12
Name inductor2: pyUBresults!$A$14:$AI$23
Name L_standard_uncertainty: #REF!
Name L_v: #REF!
Name label: #REF!
Name multiplier: #REF!
Name Nominal_Value: #REF!
Name Old_date: #REF!
Name Old_Inductance: #REF!
Name Old_Resistance: #REF!
Name Params: #REF!
Name pyvalues: pyUBresults!$Z$2:$AQ$23
Name R_4A: #REF!
Name R_4B: #REF!
Name R_4C: #REF!
Name R_standard_uncertainty: #REF!
Name R_v: #REF!
Name Range: #REF!
Name Rangex: #REF!
Name Record: #REF!
Name Reports: #REF!
Name Resistance: #REF!
Name Results: #REF!
Name ub_uncertainty: #REF!
Name Uncertainty: #REF!
Name zeros: #REF!

Sheet Commentary
A1: 44041
A3: Worksheet 'pyUBreadings' requires the user to enter all the dial readings and settings of the UB as well as estimates of the uncertainty in temperature and in the temperature coefficients for resistance and inductance. In general it is set up not to apply any temperature corrections, just to evaluate the uncertainty.
A5: Use the UniversalBridge3 project to process the input data. This uses the latest ubdict.csv file for corrections to the Universal Bridge. Running 'calculate_imp.py' produces a new 'indResults.xlsx'. Paste these results into the 'pyUBresults' worksheet of this spreadsheet and, if correctly pasted, should immediately produce the report in the'pyReport' worksheet. Note that there are two named blocks in 'pyUBresults' and so the new data should just be pasted over the old data in order to preserve the inductor1 and inductor2 named blocks.
A7: You should check that the input data listed in 'pyUBresults' matches the input data in 'pyUBreadings', just in case the wrong file names are enterd in 'calculate_imp.py'.

Sheet pyUBreadings
A1: Template for impedances
A2: 1 | B2: 2 | D2: 3 | E2: 4 | F2: 5 | G2: 6 | H2: 7 | I2: 8 | J2: 9 | K2: 10 | L2: 11 | M2: 12 | N2: 13 | O2: 14 | P2: 15 | Q2: 16 | R2: 17
A3: Impedance | B3: Muirhead A-517 | E3: Client | K3: Enter, say, 5 ppm as 5e-6
A4: Date from | B4: 43803 | E4: Job number | F4: 96330136 | K4: 1 sigma uncertainties from specifications
A5: to | B5: 43804 | E5: S Number | F5: S22075
D6: Data from lab book | F6: check! | G6: check! | H6: Data from specifications and other sources
A7: Item | B7: Nominal Frequency | C7: Range | D7: xdial | E7: rdial | F7: Frequency | G7: Temperature | H7: u | I7: df | J7: Temp coeff L | K7: u | L7: df | M7: Temp coeff R | N7: u | O7: df | P7: Other | Q7: u | R7: df
B8: Hz | F8: Hz | G8: °C
A9: L0 | B9: 1591.5 | C9: 4Z | D9: 3 | E9: 419 | F9: 1591 | G9: 20 | H9: 0.5 | I9: 10 | J9: 5e-05 | K9: =0.000005 -> 5e-06 | L9: 10 | M9: 0.004 | N9: 0.0004 | O9: 10
A10: L1 | B10: 1591.5 | C10: 4Z | D10: 101493 | E10: 195221 | F10: 1591 | G10: 20 | H10: 0.5 | I10: 10 | J10: 5e-05 | K10: 5e-06 | L10: 10 | M10: 0.004 | N10: 0.0004 | O10: 10
A11: L2 | B11: 1591.5 | C11: 4Z | D11: 199887 | E11: 280480 | F11: 1591 | G11: 20 | H11: 0.5 | I11: 10 | J11: 5e-05 | K11: 5e-06 | L11: 10 | M11: 0.004 | N11: 0.0004 | O11: 10
A12: L3 | B12: 1591.5 | C12: 4Z | D12: 292655 | E12: 345191 | F12: 1591 | G12: 20 | H12: 0.5 | I12: 10 | J12: 5e-05 | K12: 5e-06 | L12: 10 | M12: 0.004 | N12: 0.0004 | O12: 10
A13: L4 | B13: 1591.5 | C13: 4Z | D13: 393464 | E13: 405970 | F13: 1591 | G13: 20 | H13: 0.5 | I13: 10 | J13: 5e-05 | K13: 5e-06 | L13: 10 | M13: 0.004 | N13: 0.0004 | O13: 10
A14: L5 | B14: 1591.5 | C14: 4Z | D14: 490515 | E14: 459475 | F14: 1591 | G14: 20 | H14: 0.5 | I14: 10 | J14: 5e-05 | K14: 5e-06 | L14: 10 | M14: 0.004 | N14: 0.0004 | O14: 10
A15: L6 | B15: 1591.5 | C15: 4Z | D15: 590969 | E15: 510603 | F15: 1591 | G15: 20 | H15: 0.5 | I15: 10 | J15: 5e-05 | K15: 5e-06 | L15: 10 | M15: 0.004 | N15: 0.0004 | O15: 10
A16: L7 | B16: 1591.5 | C16: 4Z | D16: 689431 | E16: 557663 | F16: 1591 | G16: 20 | H16: 0.5 | I16: 10 | J16: 5e-05 | K16: 5e-06 | L16: 10 | M16: 0.004 | N16: 0.0004 | O16: 10
A17: L8 | B17: 1591.5 | C17: 4Z | D17: 788816 | E17: 603296 | F17: 1591 | G17: 20 | H17: 0.5 | I17: 10 | J17: 5e-05 | K17: 5e-06 | L17: 10 | M17: 0.004 | N17: 0.0004 | O17: 10
A18: L9 | B18: 1591.5 | C18: 4Z | D18: 889889 | E18: 648646 | F18: 1591 | G18: 20 | H18: 0.5 | I18: 10 | J18: 5e-05 | K18: 5e-06 | L18: 10 | M18: 0.004 | N18: 0.0004 | O18: 10
A19: L10 | B19: 1591.5 | C19: 4Z | D19: 1011051 | E19: 699208 | F19: 1591 | G19: 20 | H19: 0.5 | I19: 10 | J19: 5e-05 | K19: 5e-06 | L19: 10 | M19: 0.004 | N19: 0.0004 | O19: 10
A20: L0 | B20: 1591.5 | C20: 5Z | D20: 0 | E20: 10 | F20: 1591 | G20: 20 | H20: 0.5 | I20: 10 | J20: 5e-05 | K20: 5e-06 | L20: 10 | M20: 0.004 | N20: 0.0004 | O20: 10
A21: L1 | B21: 1591.5 | C21: 5Z | D21: 103928 | E21: 168318 | F21: 1591 | G21: 20 | H21: 0.5 | I21: 10 | J21: 5e-05 | K21: 5e-06 | L21: 10 | M21: 0.004 | N21: 0.0004 | O21: 10
... A30: L10 | B30: 1591.5 | C30: 5Z | D30: 988170 | E30: 601673 | F30: 1591 | G30: 20 | H30: 0.5 | I30: 10 | J30: 5e-05 | K30: 5e-06 | L30: 10 | M30: 0.004 | N30: 0.0004 | O30: 10

Sheet pyUBresults
A1: Item | B1: Label | C1: Range | D1: xDial | E1: rDial | F1: frequency | G1: temperature | H1: utemp | I1: dftemp | J1: alphax | K1: ualphax | L1: dfalphax | M1: alphar | N1: ualphar | O1: dfalphr | P1: x | Q1: ux | R1: kx | S1: r | T1: ur | U1: kr | V1: cmcx | W1: cmcr | X1: ux/cmcx | Y1: ur/cmcr | Z1: label | AA1: multiplier for R | AB1: R | AC1: uR | AD1: k | AE1: multiplier for L | AF1: L | AG1: uL | AH1: k | AI1: nom Freq
A2: L0 | B2: 1591.5 | C2: 4Z | D2: 3 | E2: 419 | F2: 1591 | G2: 20 | H2: 0.5 | I2: 10 | J2: 5e-05 | K2: 5e-06 | L2: 10 | M2: 0.004 | N2: 0.0004 | O2: 10 | P2: 0 | Q2: 0 | R2: 0 | S2: 0 | T2: 0 | U2: 0 | V2: 1.2570711e-07 | W2: 0.0012570712 | X2: =Q2/V2 -> 0 | Y2: =T2/W2 -> 0 | Z2: =A2&B2 -> L01591.5 | AA2: 1000 | AB2: =AA2*S2 -> 0 | AC2: =AA2*T2 -> 0 | AD2: =U2 -> 0 | AE2: 1000000 | AF2: =AE2*P2 -> 0 | AG2: =AE2*Q2 -> 0 | AH2: =R2 -> 0 | AI2: =B2 -> 1591.5
A3: L1 | B3: 1591.5 | C3: 4Z | D3: 101493 | E3: 195221 | F3: 1591 | G3: 20 | H3: 0.5 | I3: 10 | J3: 5e-05 | K3: 5e-06 | L3: 10 | M3: 0.004 | N3: 0.0004 | O3: 10 | P3: 0.010151103 | Q3: 9.0487916e-07 | R3: 2.0132932 | S3: 19.481361 | T3: 0.11565455 | U3: 2.0839786 | V3: 1.9073916e-07 | W3: 0.0016387326 | X3: =Q3/V3 -> 4.744066 | Y3: =T3/W3 -> 70.575611 | Z3: =A3&B3 -> L11591.5 | AA3: 1000 | AB3: =AA3*S3 -> 19481.361 | AC3: =AA3*T3 -> 115.65455 | AD3: =U3 -> 2.0839786 | AE3: 1000000 | AF3: =AE3*P3 -> 10151.103 | AG3: =AE3*Q3 -> 0.90487916 | AH3: =R3 -> 2.0132932 | AI3: =B3 -> 1591.5
A4: L2 | B4: 1591.5 | C4: 4Z | D4: 199887 | E4: 280480 | F4: 1591 | G4: 20 | H4: 0.5 | I4: 10 | J4: 5e-05 | K4: 5e-06 | L4: 10 | M4: 0.004 | N4: 0.0004 | O4: 10 | P4: 0.019992542 | Q4: 1.6330887e-06 | R4: 2.0348176 | S4: 28.007769 | T4: 0.16622081 | U4: 2.0839695 | V4: 3.0811192e-07 | W4: 0.0023940707 | X4: =Q4/V4 -> 5.3003101 | Y4: =T4/W4 -> 69.430198 | Z4: =A4&B4 -> L21591.5 | AA4: 1000 | AB4: =AA4*S4 -> 28007.769 | AC4: =AA4*T4 -> 166.22081 | AD4: =U4 -> 2.0839695 | AE4: 1000000 | AF4: =AE4*P4 -> 19992.542 | AG4: =AE4*Q4 -> 1.6330887 | AH4: =R4 -> 2.0348176 | AI4: =B4 -> 1591.5
A5: L3 | B5: 1591.5 | C5: 4Z | D5: 292655 | E5: 345191 | F5: 1591 | G5: 20 | H5: 0.5 | I5: 10 | J5: 5e-05 | K5: 5e-06 | L5: 10 | M5: 0.004 | N5: 0.0004 | O5: 10 | P5: 0.029271265 | Q5: 2.3493937e-06 | R5: 2.0412321 | S5: 34.479255 | T5: 0.20463646 | U5: 2.0838422 | V5: 4.3003673e-07 | W5: 0.0032221185 | X5: =Q5/V5 -> 5.4632395 | Y5: =T5/W5 -> 63.50991 | Z5: =A5&B5 -> L31591.5 | AA5: 1000 | AB5: =AA5*S5 -> 34479.255 | AC5: =AA5*T5 -> 204.63646 | AD5: =U5 -> 2.0838422 | AE5: 1000000 | AF5: =AE5*P5 -> 29271.265 | AG5: =AE5*Q5 -> 2.3493937 | AH5: =R5 -> 2.0412321 | AI5: =B5 -> 1591.5
A6: L4 | B6: 1591.5 | C6: 4Z | D6: 393464 | E6: 405970 | F6: 1591 | G6: 20 | H6: 0.5 | I6: 10 | J6: 5e-05 | K6: 5e-06 | L6: 10 | M6: 0.004 | N6: 0.0004 | O6: 10 | P6: 0.039354254 | Q6: 3.1365375e-06 | R6: 2.04407 | S6: 40.557517 | T6: 0.24074709 | U6: 2.0836754 | V6: 5.665789e-07 | W6: 0.0041702645 | X6: =Q6/V6 -> 5.5359236 | Y6: =T6/W6 -> 57.729452 | Z6: =A6&B6 -> L41591.5 | AA6: 1000 | AB6: =AA6*S6 -> 40557.517 | AC6: =AA6*T6 -> 240.74709 | AD6: =U6 -> 2.0836754 | AE6: 1000000 | AF6: =AE6*P6 -> 39354.254 | AG6: =AE6*Q6 -> 3.1365375 | AH6: =R6 -> 2.04407 | AI6: =B6 -> 1591.5
A7: L5 | B7: 1591.5 | C7: 4Z | D7: 490515 | E7: 459475 | F7: 1591 | G7: 20 | H7: 0.5 | I7: 10 | J7: 5e-05 | K7: 5e-06 | L7: 10 | M7: 0.004 | N7: 0.0004 | O7: 10 | P7: 0.049061365 | Q7: 3.8978709e-06 | R7: 2.0453976 | S7: 45.908336 | T7: 0.27255691 | U7: 2.0835125 | V7: 6.9978205e-07 | W7: 0.005105344 | X7: =Q7/V7 -> 5.5701213 | Y7: =T7/W7 -> 53.386592 | Z7: =A7&B7 -> L51591.5 | AA7: 1000 | AB7: =AA7*S7 -> 45908.336 | AC7: =AA7*T7 -> 272.55691 | AD7: =U7 -> 2.0835125 | AE7: 1000000 | AF7: =AE7*P7 -> 49061.365 | AG7: =AE7*Q7 -> 3.8978709 | AH7: =R7 -> 2.0453976 | AI7: =B7 -> 1591.5
A8: L6 | B8: 1591.5 | C8: 4Z | D8: 590969 | E8: 510603 | F8: 1591 | G8: 20 | H8: 0.5 | I8: 10 | J8: 5e-05 | K8: 5e-06 | L8: 10 | M8: 0.004 | N8: 0.0004 | O8: 10 | P8: 0.059108847 | Q8: 4.6877011e-06 | R8: 2.0461689 | S8: 51.02144 | T8: 0.30297343 | U8: 2.0833439 | V8: 8.3857762e-07 | W8: 0.0060852447 | X8: =Q8/V8 -> 5.5900623 | Y8: =T8/W8 -> 49.788208 | Z8: =A8&B8 -> L61591.5 | AA8: 1000 | AB8: =AA8*S8 -> 51021.44 | AC8: =AA8*T8 -> 302.97343 | AD8: =U8 -> 2.0833439 | AE8: 1000000 | AF8: =AE8*P8 -> 59108.847 | AG8: =AE8*Q8 -> 4.6877011 | AH8: =R8 -> 2.0461689 | AI8: =B8 -> 1591.5
A9: L7 | B9: 1591.5 | C9: 4Z | D9: 689431 | E9: 557663 | F9: 1591 | G9: 20 | H9: 0.5 | I9: 10 | J9: 5e-05 | K9: 5e-06 | L9: 10 | M9: 0.004 | N9: 0.0004 | O9: 10 | P9: 0.068957088 | Q9: 5.4628843e-06 | R9: 2.0466333 | S9: 55.727721 | T9: 0.33098666 | U9: 2.0831816 | V9: 9.7514938e-07 | W9: 0.0070527335 | X9: =Q9/V9 -> 5.6021 | Y9: =T9/W9 -> 46.930266 | Z9: =A9&B9 -> L71591.5 | AA9: 1000 | AB9: =AA9*S9 -> 55727.721 | AC9: =AA9*T9 -> 330.98666 | AD9: =U9 -> 2.0831816 | AE9: 1000000 | AF9: =AE9*P9 -> 68957.088 | AG9: =AE9*Q9 -> 5.4628843 | AH9: =R9 -> 2.0466333 | AI9: =B9 -> 1591.5
A10: L8 | B10: 1591.5 | C10: 4Z | D10: 788816 | E10: 603296 | F10: 1591 | G10: 20 | H10: 0.5 | I10: 10 | J10: 5e-05 | K10: 5e-06 | L10: 10 | M10: 0.004 | N10: 0.0004 | O10: 10 | P10: 0.078897647 | Q10: 6.2459726e-06 | R10: 2.0469427 | S10: 60.291293 | T10: 0.35816322 | U10: 2.0830244 | V10: 1.1133373e-06 | W10: 0.0080338376 | X10: =Q10/V10 -> 5.6101348 | Y10: =T10/W10 -> 44.581834 | Z10: =A10&B10 -> L81591.5 | AA10: 1000 | AB10: =AA10*S10 -> 60291.293 | AC10: =AA10*T10 -> 358.16322 | AD10: =U10 -> 2.0830244 | AE10: 1000000 | AF10: =AE10*P10 -> 78897.647 | AG10: =AE10*Q10 -> 6.2459726 | AH10: =R10 -> 2.0469427 | AI10: =B10 -> 1591.5
A11: L9 | B11: 1591.5 | C11: 4Z | D11: 889889 | E11: 648646 | F11: 1591 | G11: 20 | H11: 0.5 | I11: 10 | J11: 5e-05 | K11: 5e-06 | L11: 10 | M11: 0.004 | N11: 0.0004 | O11: 10 | P11: 0.089007042 | Q11: 7.0428022e-06 | R11: 2.0471602 | S11: 64.826563 | T11: 0.38518058 | U11: 2.0828741 | V11: 1.2541062e-06 | W11: 0.0090348242 | X11: =Q11/V11 -> 5.6157941 | Y11: =T11/W11 -> 42.63288 | Z11: =A11&B11 -> L91591.5 | AA11: 1000 | AB11: =AA11*S11 -> 64826.563 | AC11: =AA11*T11 -> 385.18058 | AD11: =U11 -> 2.0828741 | AE11: 1000000 | AF11: =AE11*P11 -> 89007.042 | AG11: =AE11*Q11 -> 7.0428022 | AH11: =R11 -> 2.0471602 | AI11: =B11 -> 1591.5
A12: L10 | B12: 1591.5 | C12: 4Z | D12: 1011051 | E12: 699208 | F12: 1591 | G12: 20 | H12: 0.5 | I12: 10 | J12: 5e-05 | K12: 5e-06 | L12: 10 | M12: 0.004 | N12: 0.0004 | O12: 10 | P12: 0.10112575 | Q12: 7.9983839e-06 | R12: 2.0473437 | S12: 69.883064 | T12: 0.41532675 | U12: 2.0826911 | V12: 1.4230536e-06 | W12: 0.010237351 | X12: =Q12/V12 -> 5.6205781 | Y12: =T12/W12 -> 40.569748 | Z12: =A12&B12 -> L101591.5 | AA12: 1000 | AB12: =AA12*S12 -> 69883.064 | AC12: =AA12*T12 -> 415.32675 | AD12: =U12 -> 2.0826911 | AE12: 1000000 | AF12: =AE12*P12 -> 101125.75 | AG12: =AE12*Q12 -> 7.9983839 | AH12: =R12 -> 2.0473437 | AI12: =B12 -> 1591.5
A13: L0 | B13: 1591.5 | C13: 5Z | D13: 0 | E13: 10 | F13: 1591 | G13: 20 | H13: 0.5 | I13: 10 | J13: 5e-05 | K13: 5e-06 | L13: 10 | M13: 0.004 | N13: 0.0004 | O13: 10 | P13: 0 | Q13: 0 | R13: 0 | S13: 0 | T13: 0 | U13: 0 | V13: 1.257071e-06 | W13: 0.01257071 | X13: =Q13/V13 -> 0 | Y13: =T13/W13 -> 0 | Z13: =A13&B13 -> L01591.5 | AA13: 1000 | AB13: =AA13*S13 -> 0 | AC13: =AA13*T13 -> 0 | AD13: =U13 -> 0 | AE13: 1000000 | AF13: =AE13*P13 -> 0 | AG13: =AE13*Q13 -> 0 | AH13: =R13 -> 0 | AI13: =B13 -> 1591.5
... A23: L10 | B23: 1591.5 | C23: 5Z | D23: 988170 | E23: 601673 | F23: 1591 | G23: 20 | H23: 0.5 | I23: 10 | J23: 5e-05 | K23: 5e-06 | L23: 10 | M23: 0.004 | N23: 0.0004 | O23: 10 | P23: 0.98837479 | Q23: 7.8171987e-05 | R23: 2.0473543 | S23: 601.69886 | T23: 3.5778719 | U23: 2.0821397 | V23: 1.3907253e-05 | W23: 0.099989162 | X23: =Q23/V23 -> 5.620951 | Y23: =T23/W23 -> 35.782598 | Z23: =A23&B23 -> L101591.5 | AA23: 1 | AB23: =AA23*S23 -> 601.69886 | AC23: =AA23*T23 -> 3.5778719 | AD23: =U23 -> 2.0821397 | AE23: 1000000 | AF23: =AE23*P23 -> 988374.79 | AG23: =AE23*Q23 -> 78.171987 | AH23: =R23 -> 2.0473543 | AI23: =B23 -> 1591.5

Sheet pyReport
C1: 2025 Coax | K1: 2020 S22075 Coax!
C3: Tap | D3: Inductance Change (mH) | E3: Expanded Uncertainty (mH) | F3: Coverage Factor | G3: Resistance Change (Ω) | H3: Expanded Uncertainty (Ω) | I3: Coverage Factor | K3: Tap | L3: Inductance Change (mH) | M3: Expanded Uncertainty (mH) | N3: Coverage Factor | O3: Resistance Change (Ω) | P3: Expanded Uncertainty (Ω) | Q3: Coverage Factor | S3: delta L /U | T3: delta R /U
A4: L10 | C4: 10 | D4: =VLOOKUP(A4, inductor1,16,FALSE())*1000 -> 101.12575 | E4: =VLOOKUP(A4,inductor1,17,FALSE())*1000 -> 0.0079983839 | F4: =VLOOKUP(A4,inductor1,18,FALSE()) -> 2.0473437 | G4: =VLOOKUP(A4,inductor1,19,FALSE()) -> 69.883064 | H4: =VLOOKUP(A4,inductor1,20,FALSE()) -> 0.41532675 | I4: =VLOOKUP(A4,inductor1,21,FALSE()) -> 2.0826911 | K4: 10 | L4: 101.12315 | M4: 0.0079573525 | N4: 2.0495416 | O4: 69.737414 | P4: 0.41444928 | Q4: 2.0826832 | S4: =(D4-L4)/E4 -> 0.32566139 | T4: =(G4-O4)/H4 -> 0.35068891
A5: L9 | C5: 9 | D5: =VLOOKUP(A5, inductor1,16,FALSE())*1000 -> 89.007042 | E5: =VLOOKUP(A5,inductor1,17,FALSE())*1000 -> 0.0070428022 | F5: =VLOOKUP(A5,inductor1,18,FALSE()) -> 2.0471602 | G5: =VLOOKUP(A5,inductor1,19,FALSE()) -> 64.826563 | H5: =VLOOKUP(A5,inductor1,20,FALSE()) -> 0.38518058 | I5: =VLOOKUP(A5,inductor1,21,FALSE()) -> 2.0828741 | K5: 9 | L5: 89.00515 | M5: 0.0070067219 | N5: 2.0493511 | O5: 64.67475 | P5: 0.38426646 | Q5: 2.082866 | S5: =(D5-L5)/E5 -> 0.26866117 | T5: =(G5-O5)/H5 -> 0.39413503
A6: L8 | C6: 8 | D6: =VLOOKUP(A6, inductor1,16,FALSE())*1000 -> 78.897647 | E6: =VLOOKUP(A6,inductor1,17,FALSE())*1000 -> 0.0062459726 | F6: =VLOOKUP(A6,inductor1,18,FALSE()) -> 2.0469427 | G6: =VLOOKUP(A6,inductor1,19,FALSE()) -> 60.291293 | H6: =VLOOKUP(A6,inductor1,20,FALSE()) -> 0.35816322 | I6: =VLOOKUP(A6,inductor1,21,FALSE()) -> 2.0830244 | K6: 8 | L6: 78.895866 | M6: 0.0062139856 | N6: 2.0491252 | O6: 60.138724 | P6: 0.35724444 | Q6: 2.0830164 | S6: =(D6-L6)/E6 -> 0.28525345 | T6: =(G6-O6)/H6 -> 0.42597624
A7: L7 | C7: 7 | D7: =VLOOKUP(A7, inductor1,16,FALSE())*1000 -> 68.957088 | E7: =VLOOKUP(A7,inductor1,17,FALSE())*1000 -> 0.0054628843 | F7: =VLOOKUP(A7,inductor1,18,FALSE()) -> 2.0466333 | G7: =VLOOKUP(A7,inductor1,19,FALSE()) -> 55.727721 | H7: =VLOOKUP(A7,inductor1,20,FALSE()) -> 0.33098666 | I7: =VLOOKUP(A7,inductor1,21,FALSE()) -> 2.0831816 | K7: 7 | L7: 68.955716 | M7: 0.0054349471 | N7: 2.048804 | O7: 55.579896 | P7: 0.33009573 | Q7: 2.0831739 | S7: =(D7-L7)/E7 -> 0.25103133 | T7: =(G7-O7)/H7 -> 0.44661872
A8: L6 | C8: 6 | D8: =VLOOKUP(A8, inductor1,16,FALSE())*1000 -> 59.108847 | E8: =VLOOKUP(A8,inductor1,17,FALSE())*1000 -> 0.0046877011 | F8: =VLOOKUP(A8,inductor1,18,FALSE()) -> 2.0461689 | G8: =VLOOKUP(A8,inductor1,19,FALSE()) -> 51.02144 | H8: =VLOOKUP(A8,inductor1,20,FALSE()) -> 0.30297343 | I8: =VLOOKUP(A8,inductor1,21,FALSE()) -> 2.0833439 | K8: 6 | L8: 59.106986 | M8: 0.0046637071 | N8: 2.0483218 | O8: 50.878058 | P8: 0.30210854 | Q8: 2.0833367 | S8: =(D8-L8)/E8 -> 0.39706153 | T8: =(G8-O8)/H8 -> 0.47325086
A9: L5 | C9: 5 | D9: =VLOOKUP(A9, inductor1,16,FALSE())*1000 -> 49.061365 | E9: =VLOOKUP(A9,inductor1,17,FALSE())*1000 -> 0.0038978709 | F9: =VLOOKUP(A9,inductor1,18,FALSE()) -> 2.0453976 | G9: =VLOOKUP(A9,inductor1,19,FALSE()) -> 45.908336 | H9: =VLOOKUP(A9,inductor1,20,FALSE()) -> 0.27255691 | I9: =VLOOKUP(A9,inductor1,21,FALSE()) -> 2.0835125 | K9: 5 | L9: 49.060415 | M9: 0.0038780123 | N9: 2.047521 | O9: 45.770191 | P9: 0.27172281 | Q9: 2.0835058 | S9: =(D9-L9)/E9 -> 0.24391839 | T9: =(G9-O9)/H9 -> 0.5068482
A10: L4 | C10: 4 | D10: =VLOOKUP(A10, inductor1,16,FALSE())*1000 -> 39.354254 | E10: =VLOOKUP(A10,inductor1,17,FALSE())*1000 -> 0.0031365375 | F10: =VLOOKUP(A10,inductor1,18,FALSE()) -> 2.04407 | G10: =VLOOKUP(A10,inductor1,19,FALSE()) -> 40.557517 | H10: =VLOOKUP(A10,inductor1,20,FALSE()) -> 0.24074709 | I10: =VLOOKUP(A10,inductor1,21,FALSE()) -> 2.0836754 | K10: 4 | L10: 39.355014 | M10: 0.0031207401 | N10: 2.0461434 | O10: 40.406805 | P10: 0.23983846 | Q10: 2.0836683 | S10: =(D10-L10)/E10 -> -0.24217633 | T10: =(G10-O10)/H10 -> 0.62601685
A11: L3 | C11: 3 | D11: =VLOOKUP(A11, inductor1,16,FALSE())*1000 -> 29.271265 | E11: =VLOOKUP(A11,inductor1,17,FALSE())*1000 -> 0.0023493937 | F11: =VLOOKUP(A11,inductor1,18,FALSE()) -> 2.0412321 | G11: =VLOOKUP(A11,inductor1,19,FALSE()) -> 34.479255 | H11: =VLOOKUP(A11,inductor1,20,FALSE()) -> 0.20463646 | I11: =VLOOKUP(A11,inductor1,21,FALSE()) -> 2.0838422 | K11: 3 | L11: 29.270435 | M11: 0.0023375661 | N11: 2.0431979 | O11: 34.347769 | P11: 0.20384136 | Q11: 2.0838362 | S11: =(D11-L11)/E11 -> 0.35342752 | T11: =(G11-O11)/H11 -> 0.64253042
A12: L2 | C12: 2 | D12: =VLOOKUP(A12, inductor1,16,FALSE())*1000 -> 19.992542 | E12: =VLOOKUP(A12,inductor1,17,FALSE())*1000 -> 0.0016330887 | F12: =VLOOKUP(A12,inductor1,18,FALSE()) -> 2.0348176 | G12: =VLOOKUP(A12,inductor1,19,FALSE()) -> 28.007769 | H12: =VLOOKUP(A12,inductor1,20,FALSE()) -> 0.16622081 | I12: =VLOOKUP(A12,inductor1,21,FALSE()) -> 2.0839695 | K12: 2 | L12: 19.991622 | M12: 0.0016250485 | N12: 2.0365457 | O12: 27.902906 | P12: 0.16558314 | Q12: 2.0839646 | S12: =(D12-L12)/E12 -> 0.5638369 | T12: =(G12-O12)/H12 -> 0.63086491
A13: L1 | C13: 1 | D13: =VLOOKUP(A13, inductor1,16,FALSE())*1000 -> 10.151103 | E13: =VLOOKUP(A13,inductor1,17,FALSE())*1000 -> 0.00090487916 | F13: =VLOOKUP(A13,inductor1,18,FALSE()) -> 2.0132932 | G13: =VLOOKUP(A13,inductor1,19,FALSE()) -> 19.481361 | H13: =VLOOKUP(A13,inductor1,20,FALSE()) -> 0.11565455 | I13: =VLOOKUP(A13,inductor1,21,FALSE()) -> 2.0839786 | K13: 1 | L13: 10.150793 | M13: 0.00090103748 | N13: 2.014287 | O13: 19.408295 | P13: 0.11520508 | Q13: 2.0839738 | S13: =(D13-L13)/E13 -> 0.34316904 | T13: =(G13-O13)/H13 -> 0.6317565
C15: Tap | D15: Inductance Change (mH) | E15: Expanded Uncertainty (mH) | F15: Coverage Factor | G15: Resistance Change (Ω) | H15: Expanded Uncertainty (Ω) | I15: Coverage Factor | K15: Tap | L15: Inductance Change (mH) | M15: Expanded Uncertainty (mH) | N15: Coverage Factor | O15: Resistance Change (Ω) | P15: Expanded Uncertainty (Ω) | Q15: Coverage Factor
A16: L10 | C16: 10 | D16: =VLOOKUP(A16, inductor2,16,FALSE())*1000 -> 988.37479 | E16: =VLOOKUP(A16,inductor2,17,FALSE())*1000 -> 0.078171987 | F16: =VLOOKUP(A16,inductor2,18,FALSE()) -> 2.0473543 | G16: =VLOOKUP(A16,inductor2,19,FALSE()) -> 601.69886 | H16: =VLOOKUP(A16,inductor2,20,FALSE()) -> 3.5778719 | I16: =VLOOKUP(A16,inductor2,21,FALSE()) -> 2.0821397 | K16: 10 | L16: 988.31176 | M16: 0.077767975 | N16: 2.0495527 | O16: 599.66811 | P16: 3.5658711 | Q16: 2.0821234 | S16: =(D16-L16)/E16 -> 0.80632067 | T16: =(G16-O16)/H16 -> 0.56758361
A17: L9 | C17: 9 | D17: =VLOOKUP(A17, inductor2,16,FALSE())*1000 -> 880.93253 | E17: =VLOOKUP(A17,inductor2,17,FALSE())*1000 -> 0.069700391 | F17: =VLOOKUP(A17,inductor2,18,FALSE()) -> 2.0471885 | G17: =VLOOKUP(A17,inductor2,19,FALSE()) -> 560.5564 | H17: =VLOOKUP(A17,inductor2,20,FALSE()) -> 3.3322519 | I17: =VLOOKUP(A17,inductor2,21,FALSE()) -> 2.0823369 | K17: 9 | L17: 880.88061 | M17: 0.069340665 | N17: 2.0493805 | O17: 558.62116 | P17: 3.3208117 | Q17: 2.0823215 | S17: =(D17-L17)/E17 -> 0.74488333 | T17: =(G17-O17)/H17 -> 0.58076068
A18: L8 | C18: 8 | D18: =VLOOKUP(A18, inductor2,16,FALSE())*1000 -> 785.2227 | E18: =VLOOKUP(A18,inductor2,17,FALSE())*1000 -> 0.062156706 | F18: =VLOOKUP(A18,inductor2,18,FALSE()) -> 2.0469832 | G18: =VLOOKUP(A18,inductor2,19,FALSE()) -> 521.31406 | H18: =VLOOKUP(A18,inductor2,20,FALSE()) -> 3.0981861 | I18: =VLOOKUP(A18,inductor2,21,FALSE()) -> 2.082509 | K18: 8 | L18: 785.17288 | M18: 0.061835839 | N18: 2.0491672 | O18: 519.65836 | P18: 3.0883941 | Q18: 2.0824959 | S18: =(D18-L18)/E18 -> 0.80151579 | T18: =(G18-O18)/H18 -> 0.53441067
A19: L7 | C19: 7 | D19: =VLOOKUP(A19, inductor2,16,FALSE())*1000 -> 691.47327 | E19: =VLOOKUP(A19,inductor2,17,FALSE())*1000 -> 0.054771426 | F19: =VLOOKUP(A19,inductor2,18,FALSE()) -> 2.0466973 | G19: =VLOOKUP(A19,inductor2,19,FALSE()) -> 482.12173 | H19: =VLOOKUP(A19,inductor2,20,FALSE()) -> 2.8645039 | I19: =VLOOKUP(A19,inductor2,21,FALSE()) -> 2.0826896 | K19: 7 | L19: 691.42555 | M19: 0.054488639 | N19: 2.04887 | O19: 480.76456 | P19: 2.856473 | Q19: 2.082679 | S19: =(D19-L19)/E19 -> 0.87130328 | T19: =(G19-O19)/H19 -> 0.47378695
A20: L6 | C20: 6 | D20: =VLOOKUP(A20, inductor2,16,FALSE())*1000 -> 593.59899 | E20: =VLOOKUP(A20,inductor2,17,FALSE())*1000 -> 0.047067334 | F20: =VLOOKUP(A20,inductor2,18,FALSE()) -> 2.0462488 | G20: =VLOOKUP(A20,inductor2,19,FALSE()) -> 440.54925 | H20: =VLOOKUP(A20,inductor2,20,FALSE()) -> 2.6167186 | I20: =VLOOKUP(A20,inductor2,21,FALSE()) -> 2.0828942 | K20: 6 | L20: 593.56637 | M20: 0.04682528 | N20: 2.0484045 | O20: 439.00856 | P20: 2.607601 | Q20: 2.0828823 | S20: =(D20-L20)/E20 -> 0.6930185 | T20: =(G20-O20)/H20 -> 0.58878679
A21: L5 | C21: 5 | D21: =VLOOKUP(A21, inductor2,16,FALSE())*1000 -> 495.57768 | E21: =VLOOKUP(A21,inductor2,17,FALSE())*1000 -> 0.039361504 | F21: =VLOOKUP(A21,inductor2,18,FALSE()) -> 2.0455224 | G21: =VLOOKUP(A21,inductor2,19,FALSE()) -> 396.96666 | H21: =VLOOKUP(A21,inductor2,20,FALSE()) -> 2.3571162 | I21: =VLOOKUP(A21,inductor2,21,FALSE()) -> 2.0831086 | K21: 5 | L21: 495.55217 | M21: 0.039159655 | N21: 2.0476504 | O21: 395.46243 | P21: 2.3482115 | Q21: 2.0830972 | S21: =(D21-L21)/E21 -> 0.64824862 | T21: =(G21-O21)/H21 -> 0.63816245
A22: L4 | C22: 4 | D22: =VLOOKUP(A22, inductor2,16,FALSE())*1000 -> 399.50578 | E22: =VLOOKUP(A22,inductor2,17,FALSE())*1000 -> 0.031825387 | F22: =VLOOKUP(A22,inductor2,18,FALSE()) -> 2.0442688 | G22: =VLOOKUP(A22,inductor2,19,FALSE()) -> 351.06392 | H22: =VLOOKUP(A22,inductor2,20,FALSE()) -> 2.0839128 | I22: =VLOOKUP(A22,inductor2,21,FALSE()) -> 2.083321 | K22: 4 | L22: 399.49036 | M22: 0.03166322 | N22: 2.046349 | O22: 349.57113 | P22: 2.0750732 | Q22: 2.0833099 | S22: =(D22-L22)/E22 -> 0.48435983 | T22: =(G22-O22)/H22 -> 0.71633856
A23: L3 | C23: 3 | D23: =VLOOKUP(A23, inductor2,16,FALSE())*1000 -> 304.65412 | E23: =VLOOKUP(A23,inductor2,17,FALSE())*1000 -> 0.02441621 | F23: =VLOOKUP(A23,inductor2,18,FALSE()) -> 2.0418164 | G23: =VLOOKUP(A23,inductor2,19,FALSE()) -> 301.982 | H23: =VLOOKUP(A23,inductor2,20,FALSE()) -> 1.7920232 | I23: =VLOOKUP(A23,inductor2,21,FALSE()) -> 2.0835304 | K23: 3 | L23: 304.63681 | M23: 0.024292413 | N23: 2.043803 | O23: 300.81163 | P23: 1.7850881 | Q23: 2.0835219 | S23: =(D23-L23)/E23 -> 0.70926526 | T23: =(G23-O23)/H23 -> 0.65309864
A24: L2 | C24: 2 | D24: =VLOOKUP(A24, inductor2,16,FALSE())*1000 -> 207.86107 | E24: =VLOOKUP(A24,inductor2,17,FALSE())*1000 -> 0.016931145 | F24: =VLOOKUP(A24,inductor2,18,FALSE()) -> 2.0357958 | G24: =VLOOKUP(A24,inductor2,19,FALSE()) -> 244.21855 | H24: =VLOOKUP(A24,inductor2,20,FALSE()) -> 1.4488727 | I24: =VLOOKUP(A24,inductor2,21,FALSE()) -> 2.08371 | K24: 2 | L24: 207.84985 | M24: 0.01684735 | N24: 2.0375585 | O24: 243.25449 | P24: 1.4431565 | Q24: 2.0837028 | S24: =(D24-L24)/E24 -> 0.6624803 | T24: =(G24-O24)/H24 -> 0.66538901
A25: L1 | C25: 1 | D25: =VLOOKUP(A25, inductor2,16,FALSE())*1000 -> 103.94954 | E25: =VLOOKUP(A25,inductor2,17,FALSE())*1000 -> 0.0092127802 | F25: =VLOOKUP(A25,inductor2,18,FALSE()) -> 2.0143517 | G25: =VLOOKUP(A25,inductor2,19,FALSE()) -> 168.31803 | H25: =VLOOKUP(A25,inductor2,20,FALSE()) -> 0.99854349 | I25: =VLOOKUP(A25,inductor2,21,FALSE()) -> 2.0837397 | K25: 1 | L25: 103.94443 | M25: 0.0091731684 | N25: 2.0153774 | O25: 167.63705 | P25: 0.99450218 | Q25: 2.0837325 | S25: =(D25-L25)/E25 -> 0.55446795 | T25: =(G25-O25)/H25 -> 0.68197093

Sheet re2019
A2: Prepare for full recalculation of the 2019 measurement
C7: On 4 December 2019 Minyu did comparison of twisted vs coax using the UB
C8: Coax | U8: For python processing
D9: L | E9: R | V9: xdial | W9: rdial
A10: 5Z | C10: 10 | D10: 988108 | E10: 599631 | F10: =E10-E$20 -> 599625 | H10: =D10-D23 -> 2660 | I10: =E10-E23 -> 3225 | J10: =F10-F23 -> 3198 | K10: =J10/D10 -> 0.0032364883 | U10: 0 | V10: =D20 -> 0 | W10: =E20 -> 6
C11: 9 | D11: 880699 | E11: 558587 | F11: =E11-E$20 -> 558581 | H11: =D11-D24 -> 2112 | I11: =E11-E24 -> 3018 | J11: =F11-F24 -> 2991 | K11: =J11/D11 -> 0.003396166 | U11: 1 | V11: =D19 -> 103923 | W11: =E19 -> 167631
C12: 8 | D12: 785011 | E12: 519627 | F12: =E12-E$20 -> 519621 | H12: =D12-D25 -> 1678 | I12: =E12-E25 -> 2304 | J12: =F12-F25 -> 2277 | K12: =J12/D12 -> 0.0029005963 | U12: 2 | V12: =D18 -> 207807 | W12: =E18 -> 243243
C13: 7 | D13: 691283 | E13: 480736 | F13: =E13-E$20 -> 480730 | H13: =D13-D26 -> 1296 | I13: =E13-E26 -> 1803 | J13: =F13-F26 -> 1776 | K13: =J13/D13 -> 0.0025691359 | U13: 3 | V13: =D17 -> 304574 | W13: =E17 -> 300796
C14: 6 | D14: 593444 | E14: 438983 | F14: =E14-E$20 -> 438977 | H14: =D14-D27 -> 969 | I14: =E14-E27 -> 1102 | J14: =F14-F27 -> 1075 | K14: =J14/D14 -> 0.0018114599 | U14: 4 | V14: =D16 -> 399408 | W14: =E16 -> 349552
C15: 5 | D15: 495450 | E15: 395440 | F15: =E15-E$20 -> 395434 | H15: =D15-D28 -> 672 | I15: =E15-E28 -> 934 | J15: =F15-F28 -> 907 | K15: =J15/D15 -> 0.001830659 | U15: 5 | V15: =D15 -> 495450 | W15: =E15 -> 395440
C16: 4 | D16: 399408 | E16: 349552 | F16: =E16-E$20 -> 349546 | H16: =D16-D29 -> 439 | I16: =E16-E29 -> 575 | J16: =F16-F29 -> 548 | K16: =J16/D16 -> 0.0013720306 | U16: 6 | V16: =D14 -> 593444 | W16: =E14 -> 438983
C17: 3 | D17: 304574 | E17: 300796 | F17: =E17-E$20 -> 300790 | H17: =D17-D30 -> 251 | I17: =E17-E30 -> 452 | J17: =F17-F30 -> 425 | K17: =J17/D17 -> 0.0013953916 | U17: 7 | V17: =D13 -> 691283 | W17: =E13 -> 480736
C18: 2 | D18: 207807 | E18: 243243 | F18: =E18-E$20 -> 243237 | H18: =D18-D31 -> 116 | I18: =E18-E31 -> 260 | J18: =F18-F31 -> 233 | K18: =J18/D18 -> 0.0011212327 | U18: 8 | V18: =D12 -> 785011 | W18: =E12 -> 519627
C19: 1 | D19: 103923 | E19: 167631 | F19: =E19-E$20 -> 167625 | H19: =D19-D32 -> 28 | I19: =E19-E32 -> 95 | J19: =F19-F32 -> 68 | K19: =J19/D19 -> 0.00065433061 | U19: 9 | V19: =D11 -> 880699 | W19: =E11 -> 558587
C20: 0 | D20: 0 | E20: 6 | U20: 10 | V20: =D10 -> 988108 | W20: =E10 -> 599631
C22: Twisted | V22: xdial | W22: rdial
C23: 10 | D23: 985448 | E23: 596406 | F23: =E23-E$33 -> 596427 | U23: 0 | V23: =D33 -> 0 | W23: =E33 -> -21
C24: 9 | D24: 878587 | E24: 555569 | F24: =E24-E$33 -> 555590 | U24: 1 | V24: =D32 -> 103895 | W24: =E32 -> 167536
C25: 8 | D25: 783333 | E25: 517323 | F25: =E25-E$33 -> 517344 | U25: 2 | V25: =D31 -> 207691 | W25: =E31 -> 242983
C26: 7 | D26: 689987 | E26: 478933 | F26: =E26-E$33 -> 478954 | U26: 3 | V26: =D30 -> 304323 | W26: =E30 -> 300344
C27: 6 | D27: 592475 | E27: 437881 | F27: =E27-E$33 -> 437902 | U27: 4 | V27: =D29 -> 398969 | W27: =E29 -> 348977
C28: 5 | D28: 494778 | E28: 394506 | F28: =E28-E$33 -> 394527 | U28: 5 | V28: =D28 -> 494778 | W28: =E28 -> 394506
C29: 4 | D29: 398969 | E29: 348977 | F29: =E29-E$33 -> 348998 | U29: 6 | V29: =D27 -> 592475 | W29: =E27 -> 437881
C30: 3 | D30: 304323 | E30: 300344 | F30: =E30-E$33 -> 300365 | U30: 7 | V30: =D26 -> 689987 | W30: =E26 -> 478933
C31: 2 | D31: 207691 | E31: 242983 | F31: =E31-E$33 -> 243004 | U31: 8 | V31: =D25 -> 783333 | W31: =E25 -> 517323
C32: 1 | D32: 103895 | E32: 167536 | F32: =E32-E$33 -> 167557 | U32: 9 | V32: =D24 -> 878587 | W32: =E24 -> 555569
C33: 0 | D33: 0 | E33: =979-1000 -> -21 | U33: 10 | V33: =D23 -> 985448 | W33: =E23 -> 596406
A35: 4Z | C35: Coax
D36: L | E36: R | V36: xdial | W36: rdial
C37: 10 | D37: 1011026 | E37: 697686 | F37: =E37-E$47 -> 697324 | H37: =D37-D50 -> 277 | I37: =E37-E50 -> 1131 | J37: =F37-F50 -> 831 | K37: =J37/D37 -> 0.00082193732 | U37: 0 | V37: =D47 -> 3 | W37: =E47 -> 362
C38: 9 | D38: 889871 | E38: 647063 | F38: =E38-E$47 -> 646701 | H38: =D38-D51 -> 212 | I38: =E38-E51 -> 960 | J38: =F38-F51 -> 660 | K38: =J38/D38 -> 0.00074168054 | U38: 1 | V38: =D46 -> 101490 | W38: =E46 -> 194431
C39: 8 | D39: 788799 | E39: 601706 | F39: =E39-E$47 -> 601344 | H39: =D39-D52 -> 166 | I39: =E39-E52 -> 816 | J39: =F39-F52 -> 516 | K39: =J39/D39 -> 0.00065415904 | U39: 2 | V39: =D45 -> 199878 | W39: =E45 -> 279371
C40: 7 | D40: 689418 | E40: 556121 | F40: =E40-E$47 -> 555759 | H40: =D40-D53 -> 126 | I40: =E40-E53 -> 796 | J40: =F40-F53 -> 496 | K40: =J40/D40 -> 0.00071944742 | U40: 3 | V40: =D44 -> 292647 | W40: =E44 -> 343815
B41: dislexic swap? | C41: 6 | D41: 590951 | E41: 509106 | F41: =E41-E$47 -> 508744 | H41: =D41-D54 -> 89 | I41: =E41-E54 -> 641 | J41: =F41-F54 -> 341 | K41: =J41/D41 -> 0.000577036 | U41: 4 | V41: =D43 -> 393472 | W41: =E43 -> 404401
C42: 5 | D42: 490506 | E42: 458031 | F42: =E42-E$47 -> 457669 | H42: =D42-D55 -> 58 | I42: =E42-E55 -> 556 | J42: =F42-F55 -> 256 | K42: =J42/D42 -> 0.00052191003 | U42: 5 | V42: =D42 -> 490506 | W42: =E42 -> 458031
C43: 4 | D43: 393472 | E43: 404401 | F43: =E43-E$47 -> 404039 | H43: =D43-D56 -> 38 | I43: =E43-E56 -> 368 | J43: =F43-F56 -> 68 | K43: =J43/D43 -> 0.00017282043 | U43: 6 | V43: =D41 -> 590951 | W43: =E41 -> 509106
C44: 3 | D44: 292647 | E44: 343815 | F44: =E44-E$47 -> 343453 | H44: =D44-D57 -> 17 | I44: =E44-E57 -> 322 | J44: =F44-F57 -> 22 | K44: =J44/D44 -> 7.5175895e-05 | U44: 7 | V44: =D40 -> 689418 | W44: =E40 -> 556121
C45: 2 | D45: 199878 | E45: 279371 | F45: =E45-E$47 -> 279009 | H45: =D45-D58 -> 6 | I45: =E45-E58 -> 296 | J45: =F45-F58 -> -4 | K45: =J45/D45 -> -2.0012207e-05 | U45: 8 | V45: =D39 -> 788799 | W45: =E39 -> 601706
C46: 1 | D46: 101490 | E46: 194431 | F46: =E46-E$47 -> 194069 | H46: =D46-D59+1 -> 1 | I46: =E46-E59 -> 296 | J46: =F46-F59 -> -4 | K46: =J46/D46 -> -3.941275e-05 | U46: 9 | V46: =D38 -> 889871 | W46: =E38 -> 647063
C47: 0 | D47: 3 | E47: 362 | U47: 10 | V47: =D37 -> 1011026 | W47: =E37 -> 697686
...

Sheet coax_v_twist
A1: On 3 December 2019 the effect of twisted lead vs coaxial connection were investigated.
A2: Measurements in AI VIII
A4: LCR
B5: Twisted lead variability
E6: normal/position ratio | G6: ppm
B7: normal | C7: 984.9926 | E7: =C$7/C7 -> 1 | G7: =(E7-1)*1000000 -> 0
B8: below | C8: 984.9485 | E8: =C$7/C8 -> 1.0000448 | G8: =(E8-1)*1000000 -> 44.773915
B9: horizontal | C9: 984.9939 | E9: =C$7/C9 -> 0.99999868 | G9: =(E9-1)*1000000 -> -1.3198051
B10: above | C10: 984.9565 | E10: =C$7/C10 -> 1.0000367 | G10: =(E10-1)*1000000 -> 36.651365
B12: change twist | E12: low/high twist ratio
B13: below | C13: 985.4645 | E13: =C8/C13 -> 0.99947639 | G13: =(E13-1)*1000000 -> -523.61095
B14: horizontal | C14: 985.4827 | E14: =C9/C14 -> 0.999504 | G14: =(E14-1)*1000000 -> -496.00059
B15: above | C15: 985.4838 | E15: =C10/C15 -> 0.99946493 | G15: =(E15-1)*1000000 -> -535.06714
B17: Above data suggests that dependence of angle of lead entry is 40 ppm
B18: Change in twist has a much larger 500 ppm shift!
B20: Coax connection | E20: horizontal/postion | I20: twisted horizontal/coax | K20: ppm
B21: below | C21: 988.2161 | E21: =C$22/C21 -> 1.0000045 | G21: =(E21-1)*1000000 -> 4.4524674 | I21: =C$14/C21 -> 0.99723401 | K21: =(I21-1)*1000000 -> -2765.9942
B22: horizontal | C22: 988.2205 | E22: =C$22/C22 -> 1 | G22: =(E22-1)*1000000 -> 0 | I22: =C$14/C22 -> 0.99722957 | K22: =(I22-1)*1000000 -> -2770.4343
B23: above | C23: 988.2231 | E23: =C$22/C23 -> 0.99999737 | G23: =(E23-1)*1000000 -> -2.6309848 | I23: =C$14/C23 -> 0.99722694 | K23: =(I23-1)*1000000 -> -2773.058
B28: The coax connection is not sensitive to lead position.
B29: The coax connection gives a higher inductance!
B30: The very large change seen here might have been caused by some other change?
E33: twisted/coax | G33: ppm
A34: UB | B34: twisted | C34: 590859 | E34: =C34/C37 -> 0.9998477 | G34: =(E34-1)*1000000 -> -152.29741
C35: 1010745 | E35: =C35/C38 -> 0.99972404 | G35: =(E35-1)*1000000 -> -275.95784
B37: coax | C37: 590949 | H37: coax reading is higher
C38: 1011024
A41: Note that the zero dial setting was not included in the checks.
K42: 28.04
A43: On 4 December 2019 Minyu did comparison of twisted vs coax using the UB | K43: 1.9604
A44: Coax
B45: Raw dial readings | E45: coax/twisted | G45: ppm | I45: coax-twisted | L45: calc-meas
A46: 10 | B46: 988108 | E46: =B46/B59 -> 1.0026993 | G46: =(E46-1)*1000000 -> 2699.2799 | I46: =B46-B59 -> 2660 | K46: =K$42*A46^K$43 -> 2559.6348 | L46: =K46-I46 -> -100.36518
A47: 9 | B47: 880699 | E47: =B47/B60 -> 1.0024039 | G47: =(E47-1)*1000000 -> 2403.8598 | I47: =B47-B60 -> 2112 | K47: =K$42*A47^K$43 -> 2081.9727 | L47: =K47-I47 -> -30.027327
A48: 8 | B48: 785011 | E48: =B48/B61 -> 1.0021421 | G48: =(E48-1)*1000000 -> 2142.1286 | I48: =B48-B61 -> 1678 | K48: =K$42*A48^K$43 -> 1652.7061 | L48: =K48-I48 -> -25.293939
A49: 7 | B49: 691283 | E49: =B49/B62 -> 1.0018783 | G49: =(E49-1)*1000000 -> 1878.2963 | I49: =B49-B62 -> 1296 | K49: =K$42*A49^K$43 -> 1272.0618 | L49: =K49-I49 -> -23.938212
A50: 6 | B50: 593444 | E50: =B50/B63 -> 1.0016355 | G50: =(E50-1)*1000000 -> 1635.512 | I50: =B50-B63 -> 969 | K50: =K$42*A50^K$43 -> 940.29845 | L50: =K50-I50 -> -28.701549
A51: 5 | B51: 495450 | E51: =B51/B64 -> 1.0013582 | G51: =(E51-1)*1000000 -> 1358.1849 | I51: =B51-B64 -> 672 | K51: =K$42*A51^K$43 -> 657.7166 | L51: =K51-I51 -> -14.283396
A52: 4 | B52: 399408 | E52: =B52/B65 -> 1.0011003 | G52: =(E52-1)*1000000 -> 1100.3361 | I52: =B52-B65 -> 439 | K52: =K$42*A52^K$43 -> 424.67473 | L52: =K52-I52 -> -14.325273
A53: 3 | B53: 304574 | E53: =B53/B66 -> 1.0008248 | G53: =(E53-1)*1000000 -> 824.78156 | I53: =B53-B66 -> 251 | K53: =K$42*A53^K$43 -> 241.61646 | L53: =K53-I53 -> -9.38354
...

Sheet LHistory
A1: History
J2: corrected for capacitance | R2: 40585
W3: as ratio | X3: Typical U
D4: S20803 | E4: S21193 | F4: S21431 | G4: S21637 | H4: S21784 | I4: S21960 | J4: S22075 | V4: twist
C5: Nominal | D5: 33850 | E5: 35523 | F5: 37148 | G5: 38883 | H5: 40585 | I5: 42236 | J5: 43803 | K5: 45646 | N5: 33850 | O5: 35523 | P5: 37148 | Q5: 38883 | R5: =H5 -> 40585 | S5: =I5 -> 42236 | T5: =J5 -> 43803 | U5: =K5 -> 45646 | V5: 45991
C6: 100 | D6: 101.1 | E6: 101.09313 | F6: 101.07754 | G6: 101.07675 | H6: 101.0934 | I6: 101.1144 | J6: =pyReport!L4 -> 101.12315 | K6: =pyReport!D4 -> 101.12575 | N6: =D6/$D6 -> 1 | O6: =E6/$D6 -> 0.99993202 | P6: =F6/$D6 -> 0.99977786 | Q6: =G6/$D6 -> 0.99977005 | R6: =H6/$D6 -> 0.99993472 | S6: =I6/$D6 -> 1.0001424 | T6: =J6/$D6 -> 1.000229 | U6: =K6/$D6 -> 1.0002547 | W6: =X6/D6 -> 6.9238378e-05 | X6: 0.0070
C7: 90 | D7: 89 | E7: 88.97367 | F7: 88.966871 | G7: 88.96156 | H7: 88.9860 | I7: 89.0063 | J7: =pyReport!L5 -> 89.00515 | K7: =pyReport!D5 -> 89.007042 | N7: =D7/$D7 -> 1 | O7: =E7/$D7 -> 0.99970416 | P7: =F7/$D7 -> 0.99962777 | Q7: =G7/$D7 -> 0.99956809 | R7: =H7/$D7 -> 0.9998427 | S7: =I7/$D7 -> 1.0000708 | T7: =J7/$D7 -> 1.0000579 | U7: =K7/$D7 -> 1.0000791 | W7: =X7/D7 -> 7.3033708e-05 | X7: 0.0065
C8: 80 | D8: 78.9 | E8: 78.868638 | F8: 78.864328 | G8: 78.858316 | H8: 78.8826 | I8: 78.9009 | J8: =pyReport!L6 -> 78.895866 | K8: =pyReport!D6 -> 78.897647 | N8: =D8/$D8 -> 1 | O8: =E8/$D8 -> 0.99960251 | P8: =F8/$D8 -> 0.99954788 | Q8: =G8/$D8 -> 0.99947168 | R8: =H8/$D8 -> 0.99977947 | S8: =I8/$D8 -> 1.0000114 | T8: =J8/$D8 -> 0.9999476 | U8: =K8/$D8 -> 0.99997018 | W8: =X8/D8 -> 7.47782e-05 | X8: 0.0059
C9: 70 | D9: 68.9 | E9: 68.933033 | F9: 68.929312 | G9: 68.9246 | H9: 68.9465 | I9: 68.9631 | J9: =pyReport!L7 -> 68.955716 | K9: =pyReport!D7 -> 68.957088 | N9: =D9/$D9 -> 1 | O9: =E9/$D9 -> 1.0004794 | P9: =F9/$D9 -> 1.0004254 | Q9: =G9/$D9 -> 1.000357 | R9: =H9/$D9 -> 1.0006749 | S9: =I9/$D9 -> 1.0009158 | T9: =J9/$D9 -> 1.0008087 | U9: =K9/$D9 -> 1.0008286 | W9: =X9/D9 -> 7.5471698e-05 | X9: 0.0052
C10: 60 | D10: 59.1 | E10: 59.088843 | F10: 59.086111 | G10: 59.082001 | H10: 59.1017 | I10: 59.1163 | J10: =pyReport!L8 -> 59.106986 | K10: =pyReport!D8 -> 59.108847 | N10: =D10/$D10 -> 1 | O10: =E10/$D10 -> 0.99981123 | P10: =F10/$D10 -> 0.99976499 | Q10: =G10/$D10 -> 0.99969545 | R10: =H10/$D10 -> 1.0000288 | S10: =I10/$D10 -> 1.0002758 | T10: =J10/$D10 -> 1.0001182 | U10: =K10/$D10 -> 1.0001497 | W10: =X10/D10 -> 7.6142132e-05 | X10: 0.0045
C11: 50 | D11: 49.05 | E11: 49.046321 | F11: 49.044478 | G11: 49.040467 | H11: 49.0579 | I11: 49.0702 | J11: =pyReport!L9 -> 49.060415 | K11: =pyReport!D9 -> 49.061365 | N11: =D11/$D11 -> 1 | O11: =E11/$D11 -> 0.999925 | P11: =F11/$D11 -> 0.99988741 | Q11: =G11/$D11 -> 0.99980565 | R11: =H11/$D11 -> 1.0001611 | S11: =I11/$D11 -> 1.0004118 | T11: =J11/$D11 -> 1.0002123 | U11: =K11/$D11 -> 1.0002317 | W11: =X11/D11 -> 7.7471967e-05 | X11: 0.0038
C12: 40 | D12: 39.35 | E12: 39.344755 | F12: 39.3434 | G12: 39.340192 | H12: 39.3546 | I12: 39.3650 | J12: =pyReport!L10 -> 39.355014 | K12: =pyReport!D10 -> 39.354254 | N12: =D12/$D12 -> 1 | O12: =E12/$D12 -> 0.9998667 | P12: =F12/$D12 -> 0.99983226 | Q12: =G12/$D12 -> 0.99975076 | R12: =H12/$D12 -> 1.0001169 | S12: =I12/$D12 -> 1.0003812 | T12: =J12/$D12 -> 1.0001274 | U12: =K12/$D12 -> 1.0001081 | W12: =X12/D12 -> 7.8780178e-05 | X12: 0.0031
C13: 30 | D13: 29.26 | E13: 29.263526 | F13: 29.26246 | G13: 29.260152 | H13: 29.2715 | I13: 29.2794 | J13: =pyReport!L11 -> 29.270435 | K13: =pyReport!D11 -> 29.271265 | N13: =D13/$D13 -> 1 | O13: =E13/$D13 -> 1.0001205 | P13: =F13/$D13 -> 1.0000841 | Q13: =G13/$D13 -> 1.0000052 | R13: =H13/$D13 -> 1.000393 | S13: =I13/$D13 -> 1.000663 | T13: =J13/$D13 -> 1.0003566 | U13: =K13/$D13 -> 1.000385 | W13: =X13/D13 -> 7.8605605e-05 | X13: 0.0023
C14: 20 | D14: 19.99 | E14: 19.987328 | F14: 19.986651 | G14: 19.984951 | H14: 19.9931 | I14: 19.9988 | J14: =pyReport!L12 -> 19.991622 | K14: =pyReport!D12 -> 19.992542 | N14: =D14/$D14 -> 1 | O14: =E14/$D14 -> 0.99986634 | P14: =F14/$D14 -> 0.99983247 | Q14: =G14/$D14 -> 0.9997474 | R14: =H14/$D14 -> 1.0001551 | S14: =I14/$D14 -> 1.0004402 | T14: =J14/$D14 -> 1.0000811 | U14: =K14/$D14 -> 1.0001272 | W14: =X14/D14 -> 8.004002e-05 | X14: 0.0016
C15: 10 | D15: 10.15 | E15: 10.148939 | F15: 10.148551 | G15: 10.147652 | H15: 10.1520 | I15: 10.1550 | J15: =pyReport!L13 -> 10.150793 | K15: =pyReport!D13 -> 10.151103 | N15: =D15/$D15 -> 1 | O15: =E15/$D15 -> 0.99989548 | P15: =F15/$D15 -> 0.99985722 | Q15: =G15/$D15 -> 0.99976868 | R15: =H15/$D15 -> 1.000197 | S15: =I15/$D15 -> 1.0004926 | T15: =J15/$D15 -> 1.0000781 | U15: =K15/$D15 -> 1.0001087 | W15: =X15/D15 -> 8.8669951e-05 | X15: 0.0009
C16: 1000 | D16: 985 | E16: 986.06226 | F16: 985.21125 | G16: 985.10009 | H16: 984.939 | I16: 985.244 | J16: =pyReport!L16-L16*1000 -> 984.9668 | K16: =pyReport!D16-L16*1000 -> 985.02983 | L16: 0.0033449573 | M16: 985.14412 | N16: =D16/$D16 -> 1 | O16: =E16/$D16 -> 1.0010784 | P16: =F16/$D16 -> 1.0002145 | Q16: =G16/$D16 -> 1.0001016 | R16: =H16/$D16 -> 0.99993807 | S16: =I16/$D16 -> 1.0002477 | T16: =J16/$D16 -> 0.99996629 | U16: =K16/$D16 -> 1.0000303 | V16: =M16/D16 -> 1.0001463 | W16: =X16/D16 -> 7.0050761e-05 | X16: 0.069
C17: 900 | D17: 879 | E17: 879.05998 | F17: 878.39588 | G17: 878.28764 | H17: 878.232 | I17: 878.380 | J17: =pyReport!L17-L17*1000 -> 878.17284 | K17: =pyReport!D17-L17*1000 -> 878.22476 | L17: 0.0027077634 | M17: 878.35199 | N17: =D17/$D17 -> 1 | O17: =E17/$D17 -> 1.0000682 | P17: =F17/$D17 -> 0.99931272 | Q17: =G17/$D17 -> 0.99918958 | R17: =H17/$D17 -> 0.99912628 | S17: =I17/$D17 -> 0.99929465 | T17: =J17/$D17 -> 0.99905898 | U17: =K17/$D17 -> 0.99911805 | V17: =M17/D17 -> 0.99926279 | W17: =X17/D17 -> 6.8259386e-05 | X17: 0.060
C18: 800 | D18: 783 | E18: 783.71158 | F18: 783.19339 | G18: 783.09621 | H18: 783.086 | I18: 783.228 | J18: =pyReport!L18-L18*1000 -> 783.03497 | K18: =pyReport!D18-L18*1000 -> 783.08479 | L18: 0.002137904 | M18: 783.15327 | N18: =D18/$D18 -> 1 | O18: =E18/$D18 -> 1.0009088 | P18: =F18/$D18 -> 1.000247 | Q18: =G18/$D18 -> 1.0001229 | R18: =H18/$D18 -> 1.0001098 | S18: =I18/$D18 -> 1.0002912 | T18: =J18/$D18 -> 1.0000447 | U18: =K18/$D18 -> 1.0001083 | V18: =M18/D18 -> 1.0001957 | W18: =X18/D18 -> 6.7688378e-05 | X18: 0.053
C19: 700 | D19: 690 | E19: 690.28749 | F19: 689.87521 | G19: 689.8051 | H19: 689.813 | I19: 689.929 | J19: =pyReport!L19-L19*1000 -> 689.79013 | K19: =pyReport!D19-L19*1000 -> 689.83785 | L19: 0.0016354185 | M19: 689.84993 | N19: =D19/$D19 -> 1 | O19: =E19/$D19 -> 1.0004166 | P19: =F19/$D19 -> 0.99981915 | Q19: =G19/$D19 -> 0.99971754 | R19: =H19/$D19 -> 0.99972899 | S19: =I19/$D19 -> 0.9998971 | T19: =J19/$D19 -> 0.99969584 | U19: =K19/$D19 -> 0.999765 | V19: =M19/D19 -> 0.99978251 | W19: =X19/D19 -> 6.8115942e-05 | X19: 0.047
C20: 600 | D20: 592 | E20: 592.71673 | F20: 592.40736 | G20: 592.35828 | H20: 592.360 | I20: 592.471 | J20: =pyReport!L20-L20*1000 -> 592.36605 | K20: =pyReport!D20-L20*1000 -> 592.39867 | L20: 0.0012003263 | M20: 592.38174 | N20: =D20/$D20 -> 1 | O20: =E20/$D20 -> 1.0012107 | P20: =F20/$D20 -> 1.0006881 | Q20: =G20/$D20 -> 1.0006052 | R20: =H20/$D20 -> 1.0006081 | S20: =I20/$D20 -> 1.0007956 | T20: =J20/$D20 -> 1.0006183 | U20: =K20/$D20 -> 1.0006734 | V20: =M20/D20 -> 1.0006448 | W20: =X20/D20 -> 6.7567568e-05 | X20: 0.040
C21: 500 | D21: 494.8 | E21: 494.97294 | F21: 494.74347 | G21: 494.70642 | H21: 494.710 | I21: 494.803 | J21: =pyReport!L21-L21*1000 -> 494.71966 | K21: =pyReport!D21-L21*1000 -> 494.74517 | L21: 0.00083250911 | M21: 494.7115 | N21: =D21/$D21 -> 1 | O21: =E21/$D21 -> 1.0003495 | P21: =F21/$D21 -> 0.99988576 | Q21: =G21/$D21 -> 0.99981086 | R21: =H21/$D21 -> 0.99981811 | S21: =I21/$D21 -> 1.0000061 | T21: =J21/$D21 -> 0.99983763 | U21: =K21/$D21 -> 0.99988919 | V21: =M21/D21 -> 0.99982115 | W21: =X21/D21 -> 6.8714632e-05 | X21: 0.034
C22: 400 | D22: 399 | E22: 399.11346 | F22: 398.95889 | G22: 398.92988 | H22: 398.931 | I22: 399.008 | J22: =pyReport!L22-L22*1000 -> 398.95849 | K22: =pyReport!D22-L22*1000 -> 398.9739 | L22: 0.00053187187 | M22: 398.93066 | N22: =D22/$D22 -> 1 | O22: =E22/$D22 -> 1.0002844 | P22: =F22/$D22 -> 0.99989698 | Q22: =G22/$D22 -> 0.99982426 | R22: =H22/$D22 -> 0.99982707 | S22: =I22/$D22 -> 1.0000201 | T22: =J22/$D22 -> 0.99989596 | U22: =K22/$D22 -> 0.9999346 | V22: =M22/D22 -> 0.99982621 | W22: =X22/D22 -> 6.7669173e-05 | X22: 0.027
C23: 300 | D23: 304.4 | E23: 304.42917 | F23: 304.3255 | G23: 304.30754 | H23: 304.305 | I23: 304.371 | J23: =pyReport!L23-L23*1000 -> 304.33846 | K23: =pyReport!D23-L23*1000 -> 304.35578 | L23: 0.00029834265 | M23: 304.30505 | N23: =D23/$D23 -> 1 | O23: =E23/$D23 -> 1.0000958 | P23: =F23/$D23 -> 0.99975526 | Q23: =G23/$D23 -> 0.99969626 | R23: =H23/$D23 -> 0.99968791 | S23: =I23/$D23 -> 0.99990473 | T23: =J23/$D23 -> 0.99979784 | U23: =K23/$D23 -> 0.99985473 | V23: =M23/D23 -> 0.99968808 | W23: =X23/D23 -> 6.8988173e-05 | X23: 0.021
C24: 200 | D24: 207.7 | E24: 207.75956 | F24: 207.69778 | G24: 207.69286 | H24: 207.691 | I24: 207.733 | J24: =pyReport!L24-L24*1000 -> 207.71794 | K24: =pyReport!D24-L24*1000 -> 207.72916 | L24: 0.00013191133 | M24: 207.68203 | N24: =D24/$D24 -> 1 | O24: =E24/$D24 -> 1.0002867 | P24: =F24/$D24 -> 0.99998933 | Q24: =G24/$D24 -> 0.99996562 | R24: =H24/$D24 -> 0.99995667 | S24: =I24/$D24 -> 1.0001589 | T24: =J24/$D24 -> 1.0000864 | U24: =K24/$D24 -> 1.0001404 | V24: =M24/D24 -> 0.99991349 | W24: =X24/D24 -> 6.7404911e-05 | X24: 0.014
C25: 100 | D25: 103.9 | E25: 103.92779 | F25: 103.9029 | G25: 103.90394 | H25: 103.900 | I25: 103.923 | J25: =pyReport!L25-L25*1000 -> 103.91191 | K25: =pyReport!D25-L25*1000 -> 103.91702 | L25: 3.2518965e-05 | M25: 103.89553 | N25: =D25/$D25 -> 1 | O25: =E25/$D25 -> 1.0002674 | P25: =F25/$D25 -> 1.0000279 | Q25: =G25/$D25 -> 1.0000379 | R25: =H25/$D25 -> 1 | S25: =I25/$D25 -> 1.0002214 | T25: =J25/$D25 -> 1.0001146 | U25: =K25/$D25 -> 1.0001638 | V25: =M25/D25 -> 0.99995695 | W25: =X25/D25 -> 7.6997113e-05 | X25: 0.008

Sheet exampleU
B3: Budget for L8 1591.5
B4: ureal(60.08704790830853,0.1713140491986457,20.451673221652594)
B5: uuttempL8 | C5: 0.12048659
B6: temperature | C6: 0.12043167
B7: Amp_phase_err | C7: 0.01332949
B8: rtempcoL8 | C8: 0.01201865
B9: Adialresureal(62.0,10.0,10.0) | C9: 0.0011776114
B10: Adialresureal(600890.0,10.0,10.0) | C10: 0.0011776114
B11: Adial_lin62 | C11: 0.0010000707
B12: Adial_lin600890 | C12: 0.0010000707
B13: Amperr | C13: 0.00084120942
B14: R4Aacdc | C14: 0.00015021762
B15: G1acdc | C15: 0.00015021762
B16: G2acdc | C16: 0.00015021762
... B35: Bdialresureal(788633.0,1.0,10.0) | C35: 0
B37: ureal(0.0788795386314938,3.031875053076101e-06,27.783955120984952)
B38: uuttempL8 | C38: 1.9769123e-06
B39: temperature | C39: 1.921136e-06
B40: Amperr | C40: 1.1043014e-06
B41: C1stab | C41: 3.9439769e-07
B42: R4Aacdc | C42: 1.9719885e-07
B43: G2acdc | C43: 1.9719885e-07
B44: xtempcoL8 | C44: 1.9719885e-07
B45: Bdialres0.0 | C45: 1.1777706e-07
B46: Bdialres788633.0 | C46: 1.1777706e-07
B47: Amp_phase_err | C47: 1.0160848e-07
B48: Bdial_lin0 | C48: 1.0002059e-07
B49: Bdial_lin788633 | C49: 1.0002059e-07
... B68: Adialres600890.0 | C68: 0

Sheet Room Conditions
A1: 43073.688 | B1: 20.9 | C1: 53.6 | G1: RH correction | H1: -2.128 | I1: from Y:\Quality\TECHPROC\E058-Lab Air Cond\loggercalibration_2017.xls
A2: 43073.691 | B2: 20.9 | C2: 53.8 | E2: Temperature | G2: RH
A3: 43073.694 | B3: 20.9 | C3: 54.8 | E3: =#REF! -> #REF! | G3: =AVERAGE(C1:C292) -> 52.280479 | H3: =G3+H1 -> 50.152479
A4: 43073.698 | B4: 20.9 | C4: 54.4 | E4: =#REF! -> #REF! | G4: =STDEV(C1:C292) -> 1.1136435
A5: 43073.701 | B5: 20.9 | C5: 54.3
A6: 43073.705 | B6: 20.8 | C6: 54.2 | E6: from GMH
A7: 43073.708 | B7: 20.8 | C7: 53.6
A8: 43073.712 | B8: 20.9 | C8: 53.4
A9: 43073.715 | B9: 20.9 | C9: 53.3
A10: 43073.719 | B10: 20.8 | C10: 53.7
A11: 43073.722 | B11: 20.8 | C11: 53
A12: 43073.726 | B12: 20.8 | C12: 52.6
A13: 43073.729 | B13: 20.9 | C13: 52.4
A14: 43073.733 | B14: 20.9 | C14: 52
A15: 43073.736 | B15: 20.9 | C15: 52
A16: 43073.74 | B16: 20.9 | C16: 52.1
A17: 43073.743 | B17: 20.9 | C17: 52
A18: 43073.747 | B18: 20.9 | C18: 51.8
... A292: 43074.698 | B292: 20.7 | C292: 53.9

Sheet Conditions
C1: Temp | F1: RH
A2: All GMH5I readings | C2: =AVERAGE(#REF!) -> #REF! | D2: =STDEV(#REF!) -> #REF!
A4: Room | C4: =#REF! -> #REF! | D4: =#REF! -> #REF! | F4: =#REF! -> #REF! | G4: =#REF! -> #REF!
