Workbook
Name alpha: Results!$D$10:$D$88
Name B_331: #REF!
Name b_331_uc: #REF!
Name beta: Results!$E$10:$E$88
Name C_1: 'Universal Bridge'!$F$4
Name C_unit_mult: '[1]Universal Bridge'!$H$41:$I$57
Name correction_c: 'Universal Bridge'!$G$12
Name corrections: 'Universal Bridge'!$F$23:$H$39
Name Data: 'Universal Bridge'!$L$2:$T$12
Name Date: Results!$A$8
Name G_1: 'Universal Bridge'!$F$8
Name G_2: 'Universal Bridge'!$F$9
Name G_unit_mult: '[1]Universal Bridge'!$K$41:$L$57
Name history: Historical!$A$99:$AG$105
Name Inductance: Results!$F$11:$F$30
Name inductor1: pyUBresults!$A$1:$AI$23
Name L_standard_uncertainty: Uncertainty!$C$24
Name L_unit_multiplier: 'Universal Bridge'!$H$41:$I$57
Name L_v: Uncertainty!$F$24
Name label: Uncertainty!$B$9
Name multiplier: 'Universal Bridge'!$F$41:$N$55
Name Nominal_Value: Report!$B$8:$B$16
Name Old_date: Results!#REF!
Name Old_Inductance: Results!$N$9:$N$30
Name Old_Resistance: Results!$Q$9:$Q$30
Name Params: Uncertainty!$S$5:$AA$59
Name previous: Historical!$B$2:$Z$22
Name R_4A: 'Universal Bridge'!$F$5
Name R_4B: 'Universal Bridge'!$F$6
Name R_4C: 'Universal Bridge'!$F$7
Name R_standard_uncertainty: Uncertainty!$C$47
Name R_unit_multiplier: 'Universal Bridge'!$K$41:$L$57
Name R_v: Uncertainty!$F$47
Name Range: Results!$C$10:$C$88
Name Rangex: Results!$B$10:$J$88
Name Record: 'Universal Bridge'!$A$5:$C$21
Name Resistance: Results!$H$11:$H$30
Name Results: Results!$B$9:$S$67
Name tag: #REF!
Name Tap_No: Results!#REF!
Name ub_uncertainty: Uncertainty!$AB$5:$AF$59
Name Uncertainty: Uncertainty!$T$5:$X$24
Name zeros: 'Universal Bridge'!$O$20:$Q$42

Sheet Commentary
A1: Start with spreadsheet S21740 from the July 2009 calibration.
A2: Remove all repeats from Results sheet
A3: Temperature correction updated for GMH51
A4: Measured frequency included, but not really necessary
A5: Results transcribed from AI VII
A6: Room data logger information for Primary Lab insered in 'Room data logger' sheet
A7: Replace 'Universal Bridge' page with the same from S21942b, change zeros block and reference.
A8: Insert uncertainty sheet from S21942b, with subsequent modifications but not to the UB uncertainty
A9: The copper temperature coefficient is identical for all, but I have left the parameter table that would allow variation by component.
A10: Add worksheet 'Histroical' to give a cleaner graphical view of previous calibrations, but some of the data is still picked up off the 'Previous History' worksheet.
A11: Resolution term for L in uncertainty, cell B40, has been made consistent with the CMC formula.
A13: On results page there is an analysis of HP4284 measurements designed to cross-check that the 600 microH result is reasonable (oscillation problem).
... A32: All worksheet in this job marked as this cell
A33: Job | B33: MSLJob3176.
A34: S_Number | B34: S22167
A35: Historical Analysing in “Historical!”

Sheet pyUBreadings
A1: Template for impedances
A2: 1 | B2: 2 | D2: 3 | E2: 4 | F2: 5 | G2: 6 | H2: 7 | I2: 8 | J2: 9 | K2: 10 | L2: 11 | M2: 12 | N2: 13 | O2: 14 | P2: 15 | Q2: 16 | R2: 17
A3: Impedance | B3: sullivan | E3: Client | F3: Babcock | K3: Enter, say, 5 ppm as 5e-6
A4: Date from | B4: 45792 | E4: Job number | F4: MSLJob3176 | K4: 1 sigma uncertainties from specifications
A5: to | B5: 46158 | E5: S Number | F5: S22167
D6: Data from lab book | F6: check! | G6: check! | H6: Data from specifications and other sources
A7: Item | B7: Nominal Frequency | C7: Range | D7: xdial | E7: rdial | F7: Frequency | G7: Temperature | H7: u | I7: df | J7: Temp coeff L | K7: u | L7: df | M7: Temp coeff R | N7: u | O7: df | P7: Other | Q7: u | R7: df
B8: Hz | F8: Hz | G8: °C
A9: coax zero | B9: 1591.5 | C9: 3Z | D9: -1 | E9: -10 | F9: 1592.54 | G9: 20.76 | H9: 0.5 | I9: 10 | J9: 2e-05 | K9: 1e-06 | L9: 10 | M9: 0.004 | N9: 0.0002 | O9: 10
A10: A1 | B10: 1591.5 | C10: 3Z | D10: 99364 | E10: 571520 | F10: 1592.34 | G10: 20.88 | H10: 0.5 | I10: 10 | J10: 2e-05 | K10: 1e-06 | L10: 10 | M10: 0.004 | N10: 0.0002 | O10: 10
A11: A2 | B11: 1591.5 | C11: 3Z | D11: 197974 | E11: 841874 | F11: 1592.19 | G11: 20.87 | H11: 0.5 | I11: 10 | J11: 2e-05 | K11: 1e-06 | L11: 10 | M11: 0.004 | N11: 0.0002 | O11: 10
A12: A3 | B12: 1591.5 | C12: 3Z | D12: 296819 | E12: 1070422 | F12: 1593.41 | G12: 20.65 | H12: 0.5 | I12: 10 | J12: 2e-05 | K12: 1e-06 | L12: 10 | M12: 0.004 | N12: 0.0002 | O12: 10
A13: A4 | B13: 1591.5 | C13: 3Z | D13: 394747 | E13: 1269967 | F13: 1592.77 | G13: 20.76 | H13: 0.5 | I13: 10 | J13: 2e-05 | K13: 1e-06 | L13: 10 | M13: 0.004 | N13: 0.0002 | O13: 10
A14: A5 | B14: 1591.5 | C14: 3Z | D14: 493101 | E14: 1447708 | F14: 1592.47 | G14: 20.82 | H14: 0.5 | I14: 10 | J14: 2e-05 | K14: 1e-06 | L14: 10 | M14: 0.004 | N14: 0.0002 | O14: 10
A15: A6 | B15: 1591.5 | C15: 3Z | D15: 591332 | E15: 1617418 | F15: 1591.8 | G15: 20.66 | H15: 0.5 | I15: 10 | J15: 2e-05 | K15: 1e-06 | L15: 10 | M15: 0.004 | N15: 0.0002 | O15: 10
A16: A7 | B16: 1591.5 | C16: 3Z | D16: 688992 | E16: 1782538 | F16: 1591.74 | G16: 20.62 | H16: 0.5 | I16: 10 | J16: 2e-05 | K16: 1e-06 | L16: 10 | M16: 0.004 | N16: 0.0002 | O16: 10
A17: A8 | B17: 1591.5 | C17: 3Z | D17: 786206 | E17: 1934775 | F17: 1591.67 | G17: 20.68 | H17: 0.5 | I17: 10 | J17: 2e-05 | K17: 1e-06 | L17: 10 | M17: 0.004 | N17: 0.0002 | O17: 10
A18: A9 | B18: 1591.5 | C18: 3Z | D18: 883126 | E18: 2081205 | F18: 1591.51 | G18: 20.72 | H18: 0.5 | I18: 10 | J18: 2e-05 | K18: 1e-06 | L18: 10 | M18: 0.004 | N18: 0.0002 | O18: 10
A19: A10 | B19: 1591.5 | C19: 3Z | D19: 980165 | E19: 2229664 | F19: 1592.88 | G19: 20.73 | H19: 0.5 | I19: 10 | J19: 2e-05 | K19: 1e-06 | L19: 10 | M19: 0.004 | N19: 0.0002 | O19: 10
A20: coax zero | B20: 1591.5 | C20: 2Z | D20: -3 | E20: -12 | F20: 1593.08 | G20: 20.79 | H20: 0.5 | I20: 10 | J20: 2e-05 | K20: 1e-06 | L20: 10 | M20: 0.004 | N20: 0.0002 | O20: 10
... A30: B10 | B30: 1591.5 | C30: 2Z | D30: 984585 | E30: 4826330 | F30: 1595.54 | G30: 19.79 | H30: 0.5 | I30: 10 | J30: 2e-05 | K30: 1e-06 | L30: 10 | M30: 0.004 | N30: 0.0002 | O30: 10
G33: =AVERAGE(G9:G31) -> 20.706364
G34: =STDEV(G9:G31) -> 0.21849148

Sheet freq_coeff
A1: Some checks were made on the frequency sensitivity of the impedance measurements.
A2: This follows from observing that the Muirhead decade inductors showed a high, but manageable, variation of resistance with frequency. (Up to 70 ppm/Hz for resistance and up to 2.5 ppm/Hz for inductance.)
A3: Conclusion is that the frequency dependence is not significant for the Sullivan inductors | T3: A10 R | V3: A10 L
A4: Assume effect is largest on the higher value inductor | S4: =H50 -> 1432.4 | T4: =K66 -> 22.225448 | U4: =L66 -> 5.3746917e-05 | V4: =N66 -> 0.0098071266 | W4: =O66 -> 1.0879577e-08
A5: A manual LCR check was made on 13/6/25 in AI VIII | S5: =H68 -> 1512.4 | T5: =K84 -> 22.235738 | U5: =L84 -> 0.00013118909 | V5: =N84 -> 0.0098060239 | W5: =O84 -> 8.2021586e-09
S6: =H86 -> 1591.5 | T6: =K102 -> 22.24564 | U6: =L102 -> 8.6568066e-05 | V6: =N102 -> 0.0098049261 | W6: =O102 -> 1.033813e-08
B7: f | C7: L | D7: R | S7: =H104 -> 1670.8 | T7: =K120 -> 22.255091 | U7: =L120 -> 0.00011833691 | V7: =N120 -> 0.0098038665 | W7: =O120 -> 7.522871e-09
B8: kHz | C8: mH | D8: Ω | S8: =H122 -> 1749.6 | T8: =K138 -> 22.264583 | U8: =L138 -> 0.00041727115 | V8: =N138 -> 0.0098028286 | W8: =O138 -> 3.797024e-08
B9: 1.592 | C9: 9.804632 | D9: 22.23322 | T9: B6 R | V9: B6 L
B10: 1.67 | C10: 9.803617 | D10: 22.24263 | S10: =H148 -> 1432.4 | T10: =K164 -> 3.5418333 | U10: =L164 -> 1.4196959e-05 | V10: =N164 -> 0.00059356703 | W10: =O164 -> 1.5776385e-09
B11: 1.592 | C11: 9.804644 | D11: 22.23452 | E11: rel delta f | F11: rel delta L | G11: rel delta R | S11: =H166 -> 1512.4 | T11: =K182 -> 3.5422766 | U11: =L182 -> 1.2811162e-05 | V11: =N182 -> 0.000593536 | W11: =O182 -> 2.0471418e-09
E12: % | F12: ppm | G12: ppm | S12: =H184 -> 1591.5 | T12: =K200 -> 3.542716 | U12: =L200 -> 2.0027412e-05 | V12: =N200 -> 0.00059350472 | W12: =O200 -> 1.5738238e-09
A13: average | B13: =AVERAGE(B9,B11) -> 1.592 | C13: =AVERAGE(C9,C11) -> 9.804638 | D13: =AVERAGE(D9,D11) -> 22.23387 | E13: =(B10/B13-1)*100 -> 4.8994975 | F13: =(C10/C13-1)*1000000 -> -104.13439 | G13: =(D10/D13-1)*1000000 -> 393.99349 | S13: =H202 -> 1670.8 | T13: =K218 -> 3.5431292 | U13: =L218 -> 1.9316159e-05 | V13: =N218 -> 0.00059347176 | W13: =O218 -> 1.4722296e-09
F14: =F13/(0.05*B11*1000) -> -1.308221 | G14: =G13/(0.05*B9*1000) -> 4.9496669 | H14: in ppm/Hz | S14: =H220 -> 1749.6 | T14: =K236 -> 3.5435492 | U14: =L236 -> 7.1406232e-05 | V14: =N236 -> 0.00059343859 | W14: =O236 -> 6.6732597e-09
A15: quick assumption is that the deltas will be at least ten times smaller for the actual frequency deviation. | Q15: Muirhead used ppm/Hz
T16: R | V16: L
B17: target f | C17: =10000/(2*PI()) -> 1591.5494 | T17: ppm/Hz | V17: ppm/Hz
C18: 1592.54 | E18: =(C18/C$17-1) -> 0.00062239291 | S18: A10 | T18: =0.0001231/T6*1000000 -> 5.5336686 | V18: =-0.00000001356/V6*1000000 -> -1.3829783
C19: 1592.34 | E19: =(C19/C$17-1) -> 0.0004967292 | S19: B6 | T19: =0.000005404/T12*1000000 -> 1.5253834 | V19: =-0.000000000405/V12*1000000 -> -0.68238716
C20: 1592.19 | E20: =(C20/C$17-1) -> 0.00040248142
C21: 1593.41 | E21: =(C21/C$17-1) -> 0.00116903
C22: 1592.77 | E22: =(C22/C$17-1) -> 0.00076690617
C23: 1592.47 | E23: =(C23/C$17-1) -> 0.00057841061
C24: 1591.8 | E24: =(C24/C$17-1) -> 0.0001574372
C25: 1591.74 | E25: =(C25/C$17-1) -> 0.00011973809
C26: 1591.67 | E26: =(C26/C$17-1) -> 7.5755788e-05
C27: 1591.51 | E27: =(C27/C$17-1) -> -2.4775177e-05
C28: 1592.88 | E28: =(C28/C$17-1) -> 0.00083602121
C30: 1593.85 | E30: =(C30/C$17-1) -> 0.0014454902
C31: 1593.64 | E31: =(C31/C$17-1) -> 0.0013135433
C32: 1593.08 | E32: =(C32/C$17-1) -> 0.00096168492
... C38: 1593.65 | E38: =(C38/C$17-1) -> 0.0013198265
B40: mean | C40: =AVERAGE(C18:C38) -> 1592.8485 | E40: =(C40/C$17-1) -> 0.00081622918
B41: sd | C41: =STDEV(C18:C38) -> 0.77511476
B42: rel sd | C42: =C41/C40 -> 0.00048662177
H43: From E4980_02_2025-06-18.csv gathered on lab machine
I44: Items A10 and B6 were measured
H45: lcr name: | I45: KeySight E4980A
H46: Name and description of Device under test: | I46: Sullivan A10 Coaxial GMH3I_2043
H47: GPIB source: | I47: <bound method MessageBasedResource.read of <'GPIBInstrument'('GPIB0::17::INSTR')>>
...

Sheet pyUBresults
A1: Item | B1: Label | C1: Range | D1: xDial | E1: rDial | F1: frequency | G1: temperature | H1: utemp | I1: dftemp | J1: alphax | K1: ualphax | L1: dfalphax | M1: alphar | N1: ualphar | O1: dfalphr | P1: x | Q1: ux | R1: kx | S1: r | T1: ur | U1: kr | V1: cmcx | W1: cmcr | X1: ux/cmcx | Y1: ur/cmcr | Z1: label | AA1: multiplier for R | AB1: R | AC1: uR | AD1: k | AE1: multiplier for L | AF1: L | AG1: uL | AH1: k | AI1: nom Freq
A2: coax zero | B2: 1591.5 | C2: 3Z | D2: -1 | E2: -10 | F2: 1592.54 | G2: 20.76 | H2: 0.5 | I2: 10 | J2: 2e-05 | K2: 1e-06 | L2: 10 | M2: 0.004 | N2: 0.0002 | O2: 10 | P2: 0 | Q2: 0 | R2: 0 | S2: 0 | T2: 0 | U2: 0 | V2: 1.2558554e-08 | W2: 0.00012558554 | X2: =Q2/V2 -> 0 | Y2: =T2/W2 -> 0 | Z2: =A2&B2 -> coax zero1591.5 | AA2: 1 | AB2: =AA2*S2 -> 0 | AC2: =AA2*T2 -> 0 | AD2: =U2 -> 0 | AE2: 1000000 | AF2: =AE2*P2 -> 0 | AG2: =AE2*Q2 -> 0 | AH2: =R2 -> 0 | AI2: =B2 -> 1591.5
A3: A1 | B3: 1591.5 | C3: 3Z | D3: 99364 | E3: 571520 | F3: 1592.34 | G3: 20.88 | H3: 0.5 | I3: 10 | J3: 2e-05 | K3: 1e-06 | L3: 10 | M3: 0.004 | N3: 0.0002 | O3: 10 | P3: 0.00099386498 | Q3: 6.3258199e-08 | R3: 1.9889169 | S3: 5.7357593 | T3: 0.033901539 | U3: 2.0825444 | V3: 1.9596327e-08 | W3: 0.00017904086 | X3: =Q3/V3 -> 3.228064 | Y3: =T3/W3 -> 189.35084 | Z3: =A3&B3 -> A11591.5 | AA3: 1 | AB3: =AA3*S3 -> 5.7357593 | AC3: =AA3*T3 -> 0.033901539 | AD3: =U3 -> 2.0825444 | AE3: 1000000 | AF3: =AE3*P3 -> 993.86498 | AG3: =AE3*Q3 -> 0.063258199 | AH3: =R3 -> 1.9889169 | AI3: =B3 -> 1591.5
A4: A2 | B4: 1591.5 | C4: 3Z | D4: 197974 | E4: 841874 | F4: 1592.19 | G4: 20.87 | H4: 0.5 | I4: 10 | J4: 2e-05 | K4: 1e-06 | L4: 10 | M4: 0.004 | N4: 0.0002 | O4: 10 | P4: 0.0019801779 | Q4: 9.8608199e-08 | R4: 2.0001778 | S4: 8.4486407 | T4: 0.049860012 | U4: 2.0836311 | V4: 3.1578034e-08 | W4: 0.00026245217 | X4: =Q4/V4 -> 3.1226832 | Y4: =T4/W4 -> 189.97752 | Z4: =A4&B4 -> A21591.5 | AA4: 1 | AB4: =AA4*S4 -> 8.4486407 | AC4: =AA4*T4 -> 0.049860012 | AD4: =U4 -> 2.0836311 | AE4: 1000000 | AF4: =AE4*P4 -> 1980.1779 | AG4: =AE4*Q4 -> 0.098608199 | AH4: =R4 -> 2.0001778 | AI4: =B4 -> 1591.5
A5: A3 | B5: 1591.5 | C5: 3Z | D5: 296819 | E5: 1070422 | F5: 1593.41 | G5: 20.65 | H5: 0.5 | I5: 10 | J5: 2e-05 | K5: 1e-06 | L5: 10 | M5: 0.004 | N5: 0.0002 | O5: 10 | P5: 0.0029688285 | Q5: 1.3834132e-07 | R5: 2.0100638 | S5: 10.732791 | T5: 0.063325694 | U5: 2.0844034 | V5: 4.4717058e-08 | W5: 0.00035545952 | X5: =Q5/V5 -> 3.0937034 | Y5: =T5/W5 -> 178.15163 | Z5: =A5&B5 -> A31591.5 | AA5: 1 | AB5: =AA5*S5 -> 10.732791 | AC5: =AA5*T5 -> 0.063325694 | AD5: =U5 -> 2.0844034 | AE5: 1000000 | AF5: =AE5*P5 -> 2968.8285 | AG5: =AE5*Q5 -> 0.13834132 | AH5: =R5 -> 2.0100638 | AI5: =B5 -> 1591.5
A6: A4 | B6: 1591.5 | C6: 3Z | D6: 394747 | E6: 1269967 | F6: 1592.77 | G6: 20.76 | H6: 0.5 | I6: 10 | J6: 2e-05 | K6: 1e-06 | L6: 10 | M6: 0.004 | N6: 0.0002 | O6: 10 | P6: 0.0039483246 | Q6: 1.7909503e-07 | R6: 2.0155571 | S6: 12.739136 | T6: 0.075136262 | U6: 2.0843526 | V6: 5.8089246e-08 | W6: 0.00045085394 | X6: =Q6/V6 -> 3.0831013 | Y6: =T6/W6 -> 166.65322 | Z6: =A6&B6 -> A41591.5 | AA6: 1 | AB6: =AA6*S6 -> 12.739136 | AC6: =AA6*T6 -> 0.075136262 | AD6: =U6 -> 2.0843526 | AE6: 1000000 | AF6: =AE6*P6 -> 3948.3246 | AG6: =AE6*Q6 -> 0.17909503 | AH6: =R6 -> 2.0155571 | AI6: =B6 -> 1591.5
A7: A5 | B7: 1591.5 | C7: 3Z | D7: 493101 | E7: 1447708 | F7: 1592.47 | G7: 20.82 | H7: 0.5 | I7: 10 | J7: 2e-05 | K7: 1e-06 | L7: 10 | M7: 0.004 | N7: 0.0002 | O7: 10 | P7: 0.0049320809 | Q7: 2.2055475e-07 | R7: 2.0188846 | S7: 14.52553 | T7: 0.085657789 | U7: 2.0843071 | V7: 7.1658558e-08 | W7: 0.00054781575 | X7: =Q7/V7 -> 3.0778563 | Y7: =T7/W7 -> 156.36241 | Z7: =A7&B7 -> A51591.5 | AA7: 1 | AB7: =AA7*S7 -> 14.52553 | AC7: =AA7*T7 -> 0.085657789 | AD7: =U7 -> 2.0843071 | AE7: 1000000 | AF7: =AE7*P7 -> 4932.0809 | AG7: =AE7*Q7 -> 0.22055475 | AH7: =R7 -> 2.0188846 | AI7: =B7 -> 1591.5
A8: A6 | B8: 1591.5 | C8: 3Z | D8: 591332 | E8: 1617418 | F8: 1591.8 | G8: 20.66 | H8: 0.5 | I8: 10 | J8: 2e-05 | K8: 1e-06 | L8: 10 | M8: 0.004 | N8: 0.0002 | O8: 10 | P8: 0.0059145833 | Q8: 2.6221215e-07 | R8: 2.0210773 | S8: 16.217946 | T8: 0.095650589 | U8: 2.0846631 | V8: 8.5298447e-08 | W8: 0.00064566203 | X8: =Q8/V8 -> 3.0740554 | Y8: =T8/W8 -> 148.14343 | Z8: =A8&B8 -> A61591.5 | AA8: 1 | AB8: =AA8*S8 -> 16.217946 | AC8: =AA8*T8 -> 0.095650589 | AD8: =U8 -> 2.0846631 | AE8: 1000000 | AF8: =AE8*P8 -> 5914.5833 | AG8: =AE8*Q8 -> 0.26221215 | AH8: =R8 -> 2.0210773 | AI8: =B8 -> 1591.5
A9: A7 | B9: 1591.5 | C9: 3Z | D9: 688992 | E9: 1782538 | F9: 1591.74 | G9: 20.62 | H9: 0.5 | I9: 10 | J9: 2e-05 | K9: 1e-06 | L9: 10 | M9: 0.004 | N9: 0.0002 | O9: 10 | P9: 0.0068913848 | Q9: 3.0385647e-07 | R9: 2.022524 | S9: 17.870752 | T9: 0.10540082 | U9: 2.0847608 | V9: 9.8912447e-08 | W9: 0.00074362057 | X9: =Q9/V9 -> 3.071974 | Y9: =T9/W9 -> 141.74005 | Z9: =A9&B9 -> A71591.5 | AA9: 1 | AB9: =AA9*S9 -> 17.870752 | AC9: =AA9*T9 -> 0.10540082 | AD9: =U9 -> 2.0847608 | AE9: 1000000 | AF9: =AE9*P9 -> 6891.3848 | AG9: =AE9*Q9 -> 0.30385647 | AH9: =R9 -> 2.022524 | AI9: =B9 -> 1591.5
A10: A8 | B10: 1591.5 | C10: 3Z | D10: 786206 | E10: 1934775 | F10: 1591.67 | G10: 20.68 | H10: 0.5 | I10: 10 | J10: 2e-05 | K10: 1e-06 | L10: 10 | M10: 0.004 | N10: 0.0002 | O10: 10 | P10: 0.0078637395 | Q10: 3.4541621e-07 | R10: 2.0235577 | S10: 19.401632 | T10: 0.11441635 | U10: 2.084676 | V10: 1.1248216e-07 | W10: 0.00084114984 | X10: =Q10/V10 -> 3.0708534 | Y10: =T10/W10 -> 136.02374 | Z10: =A10&B10 -> A81591.5 | AA10: 1 | AB10: =AA10*S10 -> 19.401632 | AC10: =AA10*T10 -> 0.11441635 | AD10: =U10 -> 2.084676 | AE10: 1000000 | AF10: =AE10*P10 -> 7863.7395 | AG10: =AE10*Q10 -> 0.34541621 | AH10: =R10 -> 2.0235577 | AI10: =B10 -> 1591.5
A11: A9 | B11: 1591.5 | C11: 3Z | D11: 883126 | E11: 2081205 | F11: 1591.51 | G11: 20.72 | H11: 0.5 | I11: 10 | J11: 2e-05 | K11: 1e-06 | L11: 10 | M11: 0.004 | N11: 0.0002 | O11: 10 | P11: 0.0088331524 | Q11: 3.8691704e-07 | R11: 2.0243345 | S11: 20.873333 | T11: 0.12308677 | U11: 2.0846133 | V11: 1.2602959e-07 | W11: 0.00093857315 | X11: =Q11/V11 -> 3.0700492 | Y11: =T11/W11 -> 131.14243 | Z11: =A11&B11 -> A91591.5 | AA11: 1 | AB11: =AA11*S11 -> 20.873333 | AC11: =AA11*T11 -> 0.12308677 | AD11: =U11 -> 2.0846133 | AE11: 1000000 | AF11: =AE11*P11 -> 8833.1524 | AG11: =AE11*Q11 -> 0.38691704 | AH11: =R11 -> 2.0243345 | AI11: =B11 -> 1591.5
A12: A10 | B12: 1591.5 | C12: 3Z | D12: 980165 | E12: 2229664 | F12: 1592.88 | G12: 20.73 | H12: 0.5 | I12: 10 | J12: 2e-05 | K12: 1e-06 | L12: 10 | M12: 0.004 | N12: 0.0002 | O12: 10 | P12: 0.0098037512 | Q12: 4.2853714e-07 | R12: 2.0249271 | S12: 22.363179 | T12: 0.1318692 | U12: 2.0846013 | V12: 1.3961559e-07 | W12: 0.0010364948 | X12: =Q12/V12 -> 3.0694074 | Y12: =T12/W12 -> 127.22611 | Z12: =A12&B12 -> A101591.5 | AA12: 1 | AB12: =AA12*S12 -> 22.363179 | AC12: =AA12*T12 -> 0.1318692 | AD12: =U12 -> 2.0846013 | AE12: 1000000 | AF12: =AE12*P12 -> 9803.7512 | AG12: =AE12*Q12 -> 0.42853714 | AH12: =R12 -> 2.0249271 | AI12: =B12 -> 1591.5
A13: coax zero | B13: 1591.5 | C13: 2Z | D13: -3 | E13: -12 | F13: 1593.08 | G13: 20.79 | H13: 0.5 | I13: 10 | J13: 2e-05 | K13: 1e-06 | L13: 10 | M13: 0.004 | N13: 0.0002 | O13: 10 | P13: 0 | Q13: 0 | R13: 0 | S13: 0 | T13: 0 | U13: 0 | V13: 1.2554297e-09 | W13: 1.2554297e-05 | X13: =Q13/V13 -> 0 | Y13: =T13/W13 -> 0 | Z13: =A13&B13 -> coax zero1591.5 | AA13: 1 | AB13: =AA13*S13 -> 0 | AC13: =AA13*T13 -> 0 | AD13: =U13 -> 0 | AE13: 1000000 | AF13: =AE13*P13 -> 0 | AG13: =AE13*Q13 -> 0 | AH13: =R13 -> 0 | AI13: =B13 -> 1591.5
... A23: B10 | B23: 1591.5 | C23: 2Z | D23: 984585 | E23: 4826330 | F23: 1595.54 | G23: 19.79 | H23: 0.5 | I23: 10 | J23: 2e-05 | K23: 1e-06 | L23: 10 | M23: 0.004 | N23: 0.0002 | O23: 10 | P23: 0.00098477955 | Q23: 4.5246523e-08 | R23: 2.01611 | S23: 4.8225753 | T23: 0.0285084 | U23: 2.0854956 | V23: 1.4661068e-08 | W23: 0.00012008796 | X23: =Q23/V23 -> 3.0861683 | Y23: =T23/W23 -> 237.396 | Z23: =A23&B23 -> B101591.5 | AA23: 1 | AB23: =AA23*S23 -> 4.8225753 | AC23: =AA23*T23 -> 0.0285084 | AD23: =U23 -> 2.0854956 | AE23: 1000000 | AF23: =AE23*P23 -> 984.77955 | AG23: =AE23*Q23 -> 0.045246523 | AH23: =R23 -> 2.01611 | AI23: =B23 -> 1591.5
A24: 1 | B24: 2 | C24: 3 | D24: 4 | E24: 5 | F24: 6 | G24: 7 | H24: 8 | I24: 9 | J24: 10 | K24: 11 | L24: 12 | M24: 13 | N24: 14 | O24: 15 | P24: 16 | Q24: 17 | R24: 18 | S24: 19 | T24: 20 | U24: 21 | V24: 22 | W24: 23 | X24: 24 | Y24: 25 | Z24: 26 | AA24: 27 | AB24: 28 | AC24: 29 | AD24: 30 | AE24: 31 | AF24: 32 | AG24: 33 | AH24: 34 | AI24: 35

Sheet pyReport
C3: Tap | D3: Inductance (µH) | E3: Expanded Uncertainty (µH) | F3: Coverage Factor | G3: Resistance (Ω) | H3: Expanded Uncertainty (Ω) | I3: Coverage Factor
A4: A1 | C4: 1 | D4: =VLOOKUP(A4, inductor1,32,FALSE()) -> 993.86498 | E4: =VLOOKUP(A4,inductor1,33,FALSE()) -> 0.063258199 | F4: =VLOOKUP(A4,inductor1,34,FALSE()) -> 1.9889169 | G4: =VLOOKUP(A4,inductor1,28,FALSE()) -> 5.7357593 | H4: =VLOOKUP(A4,inductor1,29,FALSE()) -> 0.033901539 | I4: =VLOOKUP(A4,inductor1,30,FALSE()) -> 2.0825444
A5: A2 | C5: 2 | D5: =VLOOKUP(A5, inductor1,32,FALSE()) -> 1980.1779 | E5: =VLOOKUP(A5,inductor1,33,FALSE()) -> 0.098608199 | F5: =VLOOKUP(A5,inductor1,34,FALSE()) -> 2.0001778 | G5: =VLOOKUP(A5,inductor1,28,FALSE()) -> 8.4486407 | H5: =VLOOKUP(A5,inductor1,29,FALSE()) -> 0.049860012 | I5: =VLOOKUP(A5,inductor1,30,FALSE()) -> 2.0836311
A6: A3 | C6: 3 | D6: =VLOOKUP(A6, inductor1,32,FALSE()) -> 2968.8285 | E6: =VLOOKUP(A6,inductor1,33,FALSE()) -> 0.13834132 | F6: =VLOOKUP(A6,inductor1,34,FALSE()) -> 2.0100638 | G6: =VLOOKUP(A6,inductor1,28,FALSE()) -> 10.732791 | H6: =VLOOKUP(A6,inductor1,29,FALSE()) -> 0.063325694 | I6: =VLOOKUP(A6,inductor1,30,FALSE()) -> 2.0844034
A7: A4 | C7: 4 | D7: =VLOOKUP(A7, inductor1,32,FALSE()) -> 3948.3246 | E7: =VLOOKUP(A7,inductor1,33,FALSE()) -> 0.17909503 | F7: =VLOOKUP(A7,inductor1,34,FALSE()) -> 2.0155571 | G7: =VLOOKUP(A7,inductor1,28,FALSE()) -> 12.739136 | H7: =VLOOKUP(A7,inductor1,29,FALSE()) -> 0.075136262 | I7: =VLOOKUP(A7,inductor1,30,FALSE()) -> 2.0843526
A8: A5 | C8: 5 | D8: =VLOOKUP(A8, inductor1,32,FALSE()) -> 4932.0809 | E8: =VLOOKUP(A8,inductor1,33,FALSE()) -> 0.22055475 | F8: =VLOOKUP(A8,inductor1,34,FALSE()) -> 2.0188846 | G8: =VLOOKUP(A8,inductor1,28,FALSE()) -> 14.52553 | H8: =VLOOKUP(A8,inductor1,29,FALSE()) -> 0.085657789 | I8: =VLOOKUP(A8,inductor1,30,FALSE()) -> 2.0843071
A9: A6 | C9: 6 | D9: =VLOOKUP(A9, inductor1,32,FALSE()) -> 5914.5833 | E9: =VLOOKUP(A9,inductor1,33,FALSE()) -> 0.26221215 | F9: =VLOOKUP(A9,inductor1,34,FALSE()) -> 2.0210773 | G9: =VLOOKUP(A9,inductor1,28,FALSE()) -> 16.217946 | H9: =VLOOKUP(A9,inductor1,29,FALSE()) -> 0.095650589 | I9: =VLOOKUP(A9,inductor1,30,FALSE()) -> 2.0846631
A10: A7 | C10: 7 | D10: =VLOOKUP(A10, inductor1,32,FALSE()) -> 6891.3848 | E10: =VLOOKUP(A10,inductor1,33,FALSE()) -> 0.30385647 | F10: =VLOOKUP(A10,inductor1,34,FALSE()) -> 2.022524 | G10: =VLOOKUP(A10,inductor1,28,FALSE()) -> 17.870752 | H10: =VLOOKUP(A10,inductor1,29,FALSE()) -> 0.10540082 | I10: =VLOOKUP(A10,inductor1,30,FALSE()) -> 2.0847608
A11: A8 | C11: 8 | D11: =VLOOKUP(A11, inductor1,32,FALSE()) -> 7863.7395 | E11: =VLOOKUP(A11,inductor1,33,FALSE()) -> 0.34541621 | F11: =VLOOKUP(A11,inductor1,34,FALSE()) -> 2.0235577 | G11: =VLOOKUP(A11,inductor1,28,FALSE()) -> 19.401632 | H11: =VLOOKUP(A11,inductor1,29,FALSE()) -> 0.11441635 | I11: =VLOOKUP(A11,inductor1,30,FALSE()) -> 2.084676
A12: A9 | C12: 9 | D12: =VLOOKUP(A12, inductor1,32,FALSE()) -> 8833.1524 | E12: =VLOOKUP(A12,inductor1,33,FALSE()) -> 0.38691704 | F12: =VLOOKUP(A12,inductor1,34,FALSE()) -> 2.0243345 | G12: =VLOOKUP(A12,inductor1,28,FALSE()) -> 20.873333 | H12: =VLOOKUP(A12,inductor1,29,FALSE()) -> 0.12308677 | I12: =VLOOKUP(A12,inductor1,30,FALSE()) -> 2.0846133
A13: A10 | C13: 10 | D13: =VLOOKUP(A13, inductor1,32,FALSE()) -> 9803.7512 | E13: =VLOOKUP(A13,inductor1,33,FALSE()) -> 0.42853714 | F13: =VLOOKUP(A13,inductor1,34,FALSE()) -> 2.0249271 | G13: =VLOOKUP(A13,inductor1,28,FALSE()) -> 22.363179 | H13: =VLOOKUP(A13,inductor1,29,FALSE()) -> 0.1318692 | I13: =VLOOKUP(A13,inductor1,30,FALSE()) -> 2.0846013
C18: Tap | D18: Inductance (µH) | E18: Expanded Uncertainty (µH) | F18: Coverage Factor | G18: Resistance (Ω) | H18: Expanded Uncertainty (Ω) | I18: Coverage Factor
A19: B1 | C19: 1 | D19: =VLOOKUP(A19, inductor1,32,FALSE()) -> 99.133066 | E19: =VLOOKUP(A19,inductor1,33,FALSE()) -> 0.0072194809 | F19: =VLOOKUP(A19,inductor1,34,FALSE()) -> 1.9977068 | G19: =VLOOKUP(A19,inductor1,28,FALSE()) -> 1.1720345 | H19: =VLOOKUP(A19,inductor1,29,FALSE()) -> 0.0069132555 | I19: =VLOOKUP(A19,inductor1,30,FALSE()) -> 2.084494
A20: B2 | C20: 2 | D20: =VLOOKUP(A20, inductor1,32,FALSE()) -> 198.9824 | E20: =VLOOKUP(A20,inductor1,33,FALSE()) -> 0.011174352 | F20: =VLOOKUP(A20,inductor1,34,FALSE()) -> 2.0028069 | G20: =VLOOKUP(A20,inductor1,28,FALSE()) -> 1.7485131 | H20: =VLOOKUP(A20,inductor1,29,FALSE()) -> 0.010309353 | I20: =VLOOKUP(A20,inductor1,30,FALSE()) -> 2.0847049
A21: B3 | C21: 3 | D21: =VLOOKUP(A21, inductor1,32,FALSE()) -> 298.20461 | E21: =VLOOKUP(A21,inductor1,33,FALSE()) -> 0.015342529 | F21: =VLOOKUP(A21,inductor1,34,FALSE()) -> 2.0065453 | G21: =VLOOKUP(A21,inductor1,28,FALSE()) -> 2.220195 | H21: =VLOOKUP(A21,inductor1,29,FALSE()) -> 0.013088804 | I21: =VLOOKUP(A21,inductor1,30,FALSE()) -> 2.0847654
A22: B4 | C22: 4 | D22: =VLOOKUP(A22, inductor1,32,FALSE()) -> 396.48117 | E22: =VLOOKUP(A22,inductor1,33,FALSE()) -> 0.019829357 | F22: =VLOOKUP(A22,inductor1,34,FALSE()) -> 2.0094056 | G22: =VLOOKUP(A22,inductor1,28,FALSE()) -> 2.8113201 | H22: =VLOOKUP(A22,inductor1,29,FALSE()) -> 0.016573666 | I22: =VLOOKUP(A22,inductor1,30,FALSE()) -> 2.0849079
A23: B5 | C23: 5 | D23: =VLOOKUP(A23, inductor1,32,FALSE()) -> 494.45456 | E23: =VLOOKUP(A23,inductor1,33,FALSE()) -> 0.024048105 | F23: =VLOOKUP(A23,inductor1,34,FALSE()) -> 2.0108968 | G23: =VLOOKUP(A23,inductor1,28,FALSE()) -> 3.2011309 | H23: =VLOOKUP(A23,inductor1,29,FALSE()) -> 0.018867818 | I23: =VLOOKUP(A23,inductor1,30,FALSE()) -> 2.084606
A24: B6 | C24: 6 | D24: =VLOOKUP(A24, inductor1,32,FALSE()) -> 593.51202 | E24: =VLOOKUP(A24,inductor1,33,FALSE()) -> 0.028324387 | F24: =VLOOKUP(A24,inductor1,34,FALSE()) -> 2.0122281 | G24: =VLOOKUP(A24,inductor1,28,FALSE()) -> 3.5658054 | H24: =VLOOKUP(A24,inductor1,29,FALSE()) -> 0.021016808 | I24: =VLOOKUP(A24,inductor1,30,FALSE()) -> 2.0845932
A25: B7 | C25: 7 | D25: =VLOOKUP(A25, inductor1,32,FALSE()) -> 691.32826 | E25: =VLOOKUP(A25,inductor1,33,FALSE()) -> 0.032580895 | F25: =VLOOKUP(A25,inductor1,34,FALSE()) -> 2.0133195 | G25: =VLOOKUP(A25,inductor1,28,FALSE()) -> 3.9245381 | H25: =VLOOKUP(A25,inductor1,29,FALSE()) -> 0.023130795 | I25: =VLOOKUP(A25,inductor1,30,FALSE()) -> 2.0845771
A26: B8 | C26: 8 | D26: =VLOOKUP(A26, inductor1,32,FALSE()) -> 789.07768 | E26: =VLOOKUP(A26,inductor1,33,FALSE()) -> 0.036778941 | F26: =VLOOKUP(A26,inductor1,34,FALSE()) -> 2.0144042 | G26: =VLOOKUP(A26,inductor1,28,FALSE()) -> 4.2255334 | H26: =VLOOKUP(A26,inductor1,29,FALSE()) -> 0.024909422 | I26: =VLOOKUP(A26,inductor1,30,FALSE()) -> 2.0849235
A27: B9 | C27: 9 | D27: =VLOOKUP(A27, inductor1,32,FALSE()) -> 887.30262 | E27: =VLOOKUP(A27,inductor1,33,FALSE()) -> 0.041046723 | F27: =VLOOKUP(A27,inductor1,34,FALSE()) -> 2.0152302 | G27: =VLOOKUP(A27,inductor1,28,FALSE()) -> 4.5463904 | H27: =VLOOKUP(A27,inductor1,29,FALSE()) -> 0.026798687 | I27: =VLOOKUP(A27,inductor1,30,FALSE()) -> 2.0848126
A28: B10 | C28: 10 | D28: =VLOOKUP(A28, inductor1,32,FALSE()) -> 984.77955 | E28: =VLOOKUP(A28,inductor1,33,FALSE()) -> 0.045246523 | F28: =VLOOKUP(A28,inductor1,34,FALSE()) -> 2.01611 | G28: =VLOOKUP(A28,inductor1,28,FALSE()) -> 4.8225753 | H28: =VLOOKUP(A28,inductor1,29,FALSE()) -> 0.0285084 | I28: =VLOOKUP(A28,inductor1,30,FALSE()) -> 2.0854956
A29: B10 | C29: 10 | D29: =VLOOKUP(A29, inductor1,32,FALSE()) -> 984.77955 | E29: =VLOOKUP(A29,inductor1,33,FALSE()) -> 0.045246523 | F29: =VLOOKUP(A29,inductor1,34,FALSE()) -> 2.01611 | G29: =VLOOKUP(A29,inductor1,28,FALSE()) -> 4.8225753 | H29: =VLOOKUP(A29,inductor1,29,FALSE()) -> 0.0285084 | I29: =VLOOKUP(A29,inductor1,30,FALSE()) -> 2.0854956

Sheet environment
A1: FCU10 Impedance
A2: Date UTC | B2: Temperature VSL | C2: Humidity VSL | D2: NZST_Time
A3: 2025-05-14 20:00:09 | B3: 20.42 | C3: 48.65 | D3: =A3+12/24 -> 45792.333 | E3: =D3 -> 45792.333
A4: 2025-05-14 20:02:08 | B4: 20.41 | C4: 48.63 | D4: =A4+12/24 -> 45792.335 | E4: =D4 -> 45792.335
A5: 2025-05-14 20:04:09 | B5: 20.41 | C5: 48.74 | D5: =A5+12/24 -> 45792.336 | E5: =D5 -> 45792.336
A6: 2025-05-14 20:06:09 | B6: 20.41 | C6: 48.68 | D6: =A6+12/24 -> 45792.338 | E6: =D6 -> 45792.338
A7: 2025-05-14 20:08:09 | B7: 20.4 | C7: 48.83 | D7: =A7+12/24 -> 45792.339 | E7: =D7 -> 45792.339
A8: 2025-05-14 20:10:08 | B8: 20.37 | C8: 48.81 | D8: =A8+12/24 -> 45792.34 | E8: =D8 -> 45792.34
A9: 2025-05-14 20:12:09 | B9: 20.39 | C9: 48.88 | D9: =A9+12/24 -> 45792.342 | E9: =D9 -> 45792.342
A10: 2025-05-14 20:14:08 | B10: 20.38 | C10: 48.95 | D10: =A10+12/24 -> 45792.343 | E10: =D10 -> 45792.343
A11: 2025-05-14 20:16:08 | B11: 20.39 | C11: 48.95 | D11: =A11+12/24 -> 45792.345 | E11: =D11 -> 45792.345
A12: 2025-05-14 20:18:08 | B12: 20.37 | C12: 49.02 | D12: =A12+12/24 -> 45792.346 | E12: =D12 -> 45792.346
A13: 2025-05-14 20:20:09 | B13: 20.4 | C13: 48.95 | D13: =A13+12/24 -> 45792.347 | E13: =D13 -> 45792.347
A14: 2025-05-14 20:22:08 | B14: 20.4 | C14: 49.01 | D14: =A14+12/24 -> 45792.349 | E14: =D14 -> 45792.349
... A1022: 2025-05-16 05:58:08 | B1022: 20.34 | C1022: 53.71 | D1022: =A1022+12/24 -> 45793.749 | E1022: =D1022 -> 45793.749

Sheet Historical
B1: Mea Date | C1: ='Previous History'!I57 -> 34971 | D1: S No. | E1: S21069 | G1: ='Previous History'!R85 -> 36749 | H1: S21384 | K1: ='Previous History'!R2 -> 38408 | L1: S21586 | O1: =Report!K2 -> 39997 | P1: S21740 | S1: =Results!B1 -> 41921 | T1: S21952 | W1: 44146 | X1: S22086 | AA1: 45792 | AB1: S22176
C2: L | D2: uL | E2: R | F2: uR | G2: L | H2: uL | I2: R | J2: uR | K2: L | L2: uL | M2: R | N2: uR | O2: L | P2: uL | Q2: R | R2: uR | S2: L | T2: uL | U2: R | V2: uR | W2: L | X2: uL | Y2: R | Z2: uR | AA2: L | AB2: uL | AC2: R | AD2: uR
B3: A1 | C3: ='Previous History'!J60 -> 994.03001 | D3: ='Previous History'!K60 -> 0.054571778 | E3: ='Previous History'!M60 -> 5.7182273 | F3: ='Previous History'!N60 -> 0.024720619 | G3: ='Previous History'!S89 -> 994.07002 | H3: ='Previous History'!T89 -> 0.054568316 | I3: ='Previous History'!V89 -> 5.6995265 | J3: ='Previous History'!W89 -> 0.024639773 | K3: ='Previous History'!T6 -> 993.99162 | L3: ='Previous History'!U6 -> 0.11571014 | M3: ='Previous History'!W6 -> 5.6915849 | N3: ='Previous History'!X6 -> 0.024610921 | O3: =Report!L8 -> 994.06462 | P3: =Report!M8 -> 0.065681418 | Q3: =Report!O8 -> 5.6775487 | R3: =Report!P8 -> 0.024544537 | S3: =Report!D8 -> 994.1995 | T3: =Report!E8 -> 0.070354849 | U3: =Report!G8 -> 5.6914915 | V3: =Report!H8 -> 0.024639447 | W3: =Report!AI8 -> 994.017 | X3: =Report!AJ8 -> 0.063 | Y3: =Report!AL8 -> 5.686 | Z3: =Report!AM8 -> 0.034 | AA3: =Report!AQ9 -> 993.86518 | AB3: =Report!AR9 -> 0.06325821 | AC3: =Report!AT9 -> 5.7357593 | AD3: =Report!AU9 -> 0.033901539
B4: A2 | C4: ='Previous History'!J61 -> 1980.3588 | D4: ='Previous History'!K61 -> 0.10366107 | E4: ='Previous History'!M61 -> 8.421949 | F4: ='Previous History'!N61 -> 0.036409149 | G4: ='Previous History'!S90 -> 1990.1204 | H4: ='Previous History'!T90 -> 0.10417808 | I4: ='Previous History'!V90 -> 8.4938522 | J4: ='Previous History'!W90 -> 0.036719995 | K4: ='Previous History'!T7 -> 1980.4119 | L4: ='Previous History'!U7 -> 5.8868538 | M4: ='Previous History'!W7 -> 8.3816784 | N4: ='Previous History'!X7 -> 0.03664029 | O4: =Report!L9 -> 1980.5079 | P4: =Report!M9 -> 0.12155553 | Q4: =Report!O9 -> 8.3614742 | R4: =Report!P9 -> 0.036146852 | S4: =Report!D9 -> 1980.7775 | T4: =Report!E9 -> 0.12681451 | U4: =Report!G9 -> 8.3824613 | V4: =Report!H9 -> 0.036289918 | W4: =Report!AI9 -> 1980.52 | X4: =Report!AJ9 -> 0.1 | Y4: =Report!AL9 -> 8.374 | Z4: =Report!AM9 -> 0.05 | AA4: =Report!AQ10 -> 1980.1783 | AB4: =Report!AR10 -> 0.098608217 | AC4: =Report!AT10 -> 8.4486407 | AD4: =Report!AU10 -> 0.049860012
B5: A3 | C5: ='Previous History'!J62 -> 2968.9979 | D5: ='Previous History'!K62 -> 0.15407063 | E5: ='Previous History'!M62 -> 10.712052 | F5: ='Previous History'!N62 -> 0.046309553 | G5: ='Previous History'!S91 -> 2973.7887 | H5: ='Previous History'!T91 -> 0.15431972 | I5: ='Previous History'!V91 -> 10.732353 | J5: ='Previous History'!W91 -> 0.046397317 | K5: ='Previous History'!T8 -> 2968.8226 | L5: ='Previous History'!U8 -> 2.0201527 | M5: ='Previous History'!W8 -> 10.661008 | N5: ='Previous History'!X8 -> 0.04616482 | O5: =Report!L10 -> 2969.2816 | P5: =Report!M10 -> 0.17972598 | Q5: =Report!O10 -> 10.635116 | R5: =Report!P10 -> 0.045975788 | S5: =Report!D10 -> 2969.7059 | T5: =Report!E10 -> 0.18621611 | U5: =Report!G10 -> 10.661872 | V5: =Report!H10 -> 0.04615965 | W5: =Report!AI10 -> 2969.42 | X5: =Report!AJ10 -> 0.14 | Y5: =Report!AL10 -> 10.653 | Z5: =Report!AM10 -> 0.063 | AA5: =Report!AQ11 -> 2968.8291 | AB5: =Report!AR11 -> 0.13834134 | AC5: =Report!AT11 -> 10.732791 | AD5: =Report!AU11 -> 0.063325694
B6: A4 | C6: ='Previous History'!J63 -> 3948.4356 | D6: ='Previous History'!K63 -> 0.20423379 | E6: ='Previous History'!M63 -> 12.706342 | F6: ='Previous History'!N63 -> 0.05493112 | G6: ='Previous History'!S92 -> 3948.9357 | H6: ='Previous History'!T92 -> 0.20425389 | I6: ='Previous History'!V92 -> 12.66634 | J6: ='Previous History'!W92 -> 0.054758187 | K6: ='Previous History'!T9 -> 3948.7118 | L6: ='Previous History'!U9 -> 0.17899555 | M6: ='Previous History'!W9 -> 12.646222 | N6: ='Previous History'!X9 -> 0.054673058 | O6: =Report!L11 -> 3948.8537 | P6: =Report!M11 -> 0.23784992 | Q6: =Report!O11 -> 12.61519 | R6: =Report!P11 -> 0.054535761 | S6: =Report!D11 -> 3949.4225 | T6: =Report!E11 -> 0.24566312 | U6: =Report!G11 -> 12.646962 | V6: =Report!H11 -> 0.054755825 | W6: =Report!AI11 -> 3949.15 | X6: =Report!AJ11 -> 0.18 | Y6: =Report!AL11 -> 12.638 | Z6: =Report!AM11 -> 0.075 | AA6: =Report!AQ12 -> 3948.3254 | AB6: =Report!AR12 -> 0.17909506 | AC6: =Report!AT12 -> 12.739136 | AD6: =Report!AU12 -> 0.075136262
B7: A5 | C7: ='Previous History'!J64 -> 4931.9739 | D7: ='Previous History'!K64 -> 0.25468229 | E7: ='Previous History'!M64 -> 14.481822 | F7: ='Previous History'!N64 -> 0.062606743 | G7: ='Previous History'!S93 -> 4932.724 | H7: ='Previous History'!T93 -> 0.25471524 | I7: ='Previous History'!V93 -> 14.43752 | J7: ='Previous History'!W93 -> 0.06241522 | K7: ='Previous History'!T10 -> 4932.4416 | L7: ='Previous History'!U10 -> 0.21647582 | M7: ='Previous History'!W10 -> 14.413923 | N7: ='Previous History'!X10 -> 0.062314743 | O7: =Report!L12 -> 4932.5965 | P7: =Report!M12 -> 0.29641068 | Q7: =Report!O12 -> 14.378433 | R7: =Report!P12 -> 0.062158453 | S7: =Report!D12 -> 4933.3499 | T7: =Report!E12 -> 0.30556722 | U7: =Report!G12 -> 14.414977 | V7: =Report!H12 -> 0.062412783 | W7: =Report!AI12 -> 4933.13 | X7: =Report!AJ12 -> 0.22 | Y7: =Report!AL12 -> 14.408 | Z7: =Report!AM12 -> 0.085 | AA7: =Report!AQ13 -> 4932.0819 | AB7: =Report!AR13 -> 0.22055479 | AC7: =Report!AT13 -> 14.52553 | AD7: =Report!AU13 -> 0.085657789
B8: A6 | C8: ='Previous History'!J65 -> 5914.202 | D8: ='Previous History'!K65 -> 0.30510597 | E8: ='Previous History'!M65 -> 16.174398 | F8: ='Previous History'!N65 -> 0.069923964 | G8: ='Previous History'!S94 -> 5915.1822 | H8: ='Previous History'!T94 -> 0.3051503 | I8: ='Previous History'!V94 -> 16.122765 | J8: ='Previous History'!W94 -> 0.069700751 | K8: ='Previous History'!T11 -> 5914.8613 | L8: ='Previous History'!U11 -> 0.25412328 | M8: ='Previous History'!W11 -> 16.099119 | N8: ='Previous History'!X11 -> 0.069599105 | O8: =Report!L13 -> 5915.0491 | P8: =Report!M13 -> 0.35499064 | Q8: =Report!O13 -> 16.05883 | R8: =Report!P13 -> 0.069423052 | S8: =Report!D13 -> 5915.9671 | T8: =Report!E13 -> 0.36551399 | U8: =Report!G13 -> 16.100456 | V8: =Report!H13 -> 0.069712738 | W8: =Report!AI13 -> 5915.88 | X8: =Report!AJ13 -> 0.26 | Y8: =Report!AL13 -> 16.09 | Z8: =Report!AM13 -> 0.1 | AA8: =Report!AQ14 -> 5914.5845 | AB8: =Report!AR14 -> 0.2622122 | AC8: =Report!AT14 -> 16.217946 | AD8: =Report!AU14 -> 0.095650589
B9: A7 | C9: ='Previous History'!J66 -> 6890.9693 | D9: ='Previous History'!K66 -> 0.35527449 | E9: ='Previous History'!M66 -> 17.822372 | F9: ='Previous History'!N66 -> 0.077048364 | G9: ='Previous History'!S95 -> 6892.0394 | H9: ='Previous History'!T95 -> 0.35532326 | I9: ='Previous History'!V95 -> 17.765799 | J9: ='Previous History'!W95 -> 0.076803794 | K9: ='Previous History'!T12 -> 6891.6899 | L9: ='Previous History'!U12 -> 0.29240337 | M9: ='Previous History'!W12 -> 17.741713 | N9: ='Previous History'!X12 -> 0.076699724 | O9: =Report!L14 -> 6891.8207 | P9: =Report!M14 -> 0.41328669 | Q9: =Report!O14 -> 17.696425 | R9: =Report!P14 -> 0.076502643 | S9: =Report!D14 -> 6892.8931 | T9: =Report!E14 -> 0.42518958 | U9: =Report!G14 -> 17.743072 | V9: =Report!H14 -> 0.076827317 | W9: =Report!AI14 -> 6892.98 | X9: =Report!AJ14 -> 0.3 | Y9: =Report!AL14 -> 17.74 | Z9: =Report!AM14 -> 0.1 | AA9: =Report!AQ15 -> 6891.3862 | AB9: =Report!AR15 -> 0.30385653 | AC9: =Report!AT15 -> 17.870752 | AD9: =Report!AU15 -> 0.10540082
B10: A8 | C10: ='Previous History'!J67 -> 7863.1258 | D10: ='Previous History'!K67 -> 0.40521194 | E10: ='Previous History'!M67 -> 19.34214 | F10: ='Previous History'!N67 -> 0.083618515 | G10: ='Previous History'!S96 -> 7864.406 | H10: ='Previous History'!T96 -> 0.40527138 | I10: ='Previous History'!V96 -> 19.281318 | J10: ='Previous History'!W96 -> 0.08335557 | K10: ='Previous History'!T13 -> 7864.0478 | L10: ='Previous History'!U13 -> 0.33083325 | M10: ='Previous History'!W13 -> 19.256869 | N10: ='Previous History'!X13 -> 0.083249655 | O10: =Report!L15 -> 7864.1515 | P10: =Report!M15 -> 0.47134832 | Q10: =Report!O15 -> 19.206342 | R10: =Report!P15 -> 0.083030327 | S10: =Report!D15 -> 7865.3283 | T10: =Report!E15 -> 0.48460715 | U10: =Report!G15 -> 19.257578 | V10: =Report!H15 -> 0.08338761 | W10: =Report!AI15 -> 7865.64 | X10: =Report!AJ15 -> 0.35 | Y10: =Report!AL15 -> 19.25 | Z10: =Report!AM15 -> 0.11 | AA10: =Report!AQ16 -> 7863.7411 | AB10: =Report!AR16 -> 0.34541627 | AC10: =Report!AT16 -> 19.401632 | AD10: =Report!AU16 -> 0.11441635
B11: A9 | C11: ='Previous History'!J68 -> 8832.1617 | D11: ='Previous History'!K68 -> 0.45499666 | E11: ='Previous History'!M68 -> 20.801806 | F11: ='Previous History'!N68 -> 0.089928834 | G11: ='Previous History'!S97 -> 8833.702 | H11: ='Previous History'!T97 -> 0.45506939 | I11: ='Previous History'!V97 -> 20.737543 | J11: ='Previous History'!W97 -> 0.089651017 | K11: ='Previous History'!T14 -> 8833.3752 | L11: ='Previous History'!U14 -> 0.36924187 | M11: ='Previous History'!W14 -> 20.713282 | N11: ='Previous History'!X14 -> 0.089545714 | O11: =Report!L16 -> 8833.2017 | P11: =Report!M16 -> 0.52923558 | Q11: =Report!O16 -> 20.657266 | R11: =Report!P16 -> 0.089303007 | S11: =Report!D16 -> 8834.5327 | T11: =Report!E16 -> 0.54384988 | U11: =Report!G16 -> 20.713051 | V11: =Report!H16 -> 0.089692541 | W11: =Report!AI16 -> 8835.46 | X11: =Report!AJ16 -> 0.39 | Y11: =Report!AL16 -> 20.71 | Z11: =Report!AM16 -> 0.12 | AA11: =Report!AQ17 -> 8833.1542 | AB11: =Report!AR17 -> 0.38691711 | AC11: =Report!AT17 -> 20.873333 | AD11: =Report!AU17 -> 0.12308677
B12: A10 | C12: ='Previous History'!J69 -> 9802.568 | D12: ='Previous History'!K69 -> 0.5048632 | E12: ='Previous History'!M69 -> 22.283173 | F12: ='Previous History'!N69 -> 0.096332969 | G12: ='Previous History'!S98 -> 9804.3182 | H12: ='Previous History'!T98 -> 0.50494661 | I12: ='Previous History'!V98 -> 22.21526 | J12: ='Previous History'!W98 -> 0.096039372 | K12: ='Previous History'!T15 -> 9803.9928 | L12: ='Previous History'!U15 -> 0.40859064 | M12: ='Previous History'!W15 -> 22.195967 | N12: ='Previous History'!X15 -> 0.095955077 | O12: =Report!L17 -> 9803.6322 | P12: =Report!M17 -> 0.58722235 | Q12: =Report!O17 -> 22.129571 | R12: =Report!P17 -> 0.095668128 | S12: =Report!D17 -> 9805.0675 | T12: =Report!E17 -> 0.60320872 | U12: =Report!G17 -> 22.189995 | V12: =Report!H17 -> 0.096090494 | W12: =Report!AI17 -> 9806.59 | X12: =Report!AJ17 -> 0.43 | Y12: =Report!AL17 -> 22.22 | Z12: =Report!AM17 -> 0.13 | AA12: =Report!AQ18 -> 9803.7532 | AB12: =Report!AR18 -> 0.42853722 | AC12: =Report!AT18 -> 22.363179 | AD12: =Report!AU18 -> 0.1318692
B13: B1 | C13: ='Previous History'!J77 -> 99.161963 | D13: ='Previous History'!K77 -> 0.0057278827 | E13: ='Previous History'!M77 -> 1.1706227 | F13: ='Previous History'!N77 -> 0.0050607496 | G13: ='Previous History'!S103 -> 99.157962 | H13: ='Previous History'!T103 -> 0.0057256554 | I13: ='Previous History'!V103 -> 1.1674995 | J13: ='Previous History'!W103 -> 0.0050472479 | K13: ='Previous History'!T22 -> 99.161121 | L13: ='Previous History'!U22 -> 0.0061381351 | M13: ='Previous History'!W22 -> 1.1671766 | N13: ='Previous History'!X22 -> 0.0050456074 | O13: =Report!L24 -> 99.156419 | P13: =Report!M24 -> 0.0066229737 | Q13: =Report!O24 -> 1.1635274 | R13: =Report!P24 -> 0.0050298841 | S13: =Report!D24 -> 99.158897 | T13: =Report!E24 -> 0.0076874384 | U13: =Report!G24 -> 1.1660993 | V13: =Report!H24 -> 0.0050478154 | W13: =Report!AI24 -> 99.1417 | X13: =Report!AJ24 -> 0.0072 | Y13: =Report!AL24 -> 1.166 | Z13: =Report!AM24 -> 0.007 | AA13: =Report!AQ24 -> 99.133086 | AB13: =Report!AR24 -> 0.0072189734 | AC13: =Report!AT24 -> 1.1720225 | AD13: =Report!AU24 -> 0.0069132555
B14: B2 | C14: ='Previous History'!J78 -> 199.02804 | D14: ='Previous History'!K78 -> 0.010708552 | E14: ='Previous History'!M78 -> 1.7456886 | F14: ='Previous History'!N78 -> 0.007546832 | G14: ='Previous History'!S104 -> 199.02804 | H14: ='Previous History'!T104 -> 0.010706438 | I14: ='Previous History'!V104 -> 1.7410403 | J14: ='Previous History'!W104 -> 0.0075267372 | K14: ='Previous History'!T23 -> 199.02636 | L14: ='Previous History'!U23 -> 0.0099933281 | M14: ='Previous History'!W23 -> 1.7402493 | N14: ='Previous History'!X23 -> 0.0075229626 | O14: =Report!L25 -> 199.02896 | P14: =Report!M25 -> 0.012292447 | Q14: =Report!O25 -> 1.7351055 | R14: =Report!P25 -> 0.0075007739 | S14: =Report!D25 -> 199.03294 | T14: =Report!E25 -> 0.013528902 | U14: =Report!G25 -> 1.7389427 | V14: =Report!H25 -> 0.0075276 | W14: =Report!AI25 -> 199.001 | X14: =Report!AJ25 -> 0.011 | Y14: =Report!AL25 -> 1.738 | Z14: =Report!AM25 -> 0.01 | AA14: =Report!AQ25 -> 198.98244 | AB14: =Report!AR25 -> 0.011174029 | AC14: =Report!AT25 -> 1.7485011 | AD14: =Report!AU25 -> 0.010309353
B15: B3 | C15: ='Previous History'!J79 -> 298.29402 | D15: ='Previous History'!K79 -> 0.015774484 | E15: ='Previous History'!M79 -> 2.2146597 | F15: ='Previous History'!N79 -> 0.0095742533 | G15: ='Previous History'!S105 -> 298.27802 | H15: ='Previous History'!T105 -> 0.015771525 | I15: ='Previous History'!V105 -> 2.2087604 | J15: ='Previous History'!W105 -> 0.00954875 | K15: ='Previous History'!T24 -> 298.2935 | L15: ='Previous History'!U24 -> 0.014440466 | M15: ='Previous History'!W24 -> 2.207796 | N15: ='Previous History'!X24 -> 0.0095441298 | O15: =Report!L26 -> 298.2944 | P15: =Report!M26 -> 0.018139306 | Q15: =Report!O26 -> 2.2012225 | R15: =Report!P26 -> 0.0095157749 | S15: =Report!D26 -> 298.30086 | T15: =Report!E26 -> 0.019544764 | U15: =Report!G26 -> 2.2060766 | V15: =Report!H26 -> 0.0095498358 | W15: =Report!AI26 -> 298.249 | X15: =Report!AJ26 -> 0.015 | Y15: =Report!AL26 -> 2.205 | Z15: =Report!AM26 -> 0.013 | AA15: =Report!AQ26 -> 298.20467 | AB15: =Report!AR26 -> 0.015342294 | AC15: =Report!AT26 -> 2.220183 | AD15: =Report!AU26 -> 0.013088804
B16: B4 | C16: ='Previous History'!J80 -> 396.55283 | D16: ='Previous History'!K80 -> 0.02087215 | E16: ='Previous History'!M80 -> 2.8021961 | F16: ='Previous History'!N80 -> 0.012114248 | G16: ='Previous History'!S106 -> 396.55083 | H16: ='Previous History'!T106 -> 0.020870504 | I16: ='Previous History'!V106 -> 2.7976669 | J16: ='Previous History'!W106 -> 0.012094667 | K16: ='Previous History'!T25 -> 396.56347 | L16: ='Previous History'!U25 -> 0.018252532 | M16: ='Previous History'!W25 -> 2.7933094 | N16: ='Previous History'!X25 -> 0.012075408 | O16: =Report!L27 -> 396.57567 | P16: =Report!M27 -> 0.023992791 | Q16: =Report!O27 -> 2.7851063 | R16: =Report!P27 -> 0.012039875 | S16: =Report!D27 -> 396.58658 | T16: =Report!E27 -> 0.025713882 | U16: =Report!G27 -> 2.7911949 | V16: =Report!H27 -> 0.012082785 | W16: =Report!AI27 -> 396.524 | X16: =Report!AJ27 -> 0.02 | Y16: =Report!AL27 -> 2.79 | Z16: =Report!AM27 -> 0.016 | AA16: =Report!AQ27 -> 396.48125 | AB16: =Report!AR27 -> 0.019829174 | AC16: =Report!AT27 -> 2.8113081 | AD16: =Report!AU27 -> 0.016573666
B17: B5 | C17: ='Previous History'!J81 -> 494.4916 | D17: ='Previous History'!K81 -> 0.025900963 | E17: ='Previous History'!M81 -> 3.1871034 | F17: ='Previous History'!N81 -> 0.01377825 | G17: ='Previous History'!S107 -> 494.4936 | H17: ='Previous History'!T107 -> 0.02589945 | I17: ='Previous History'!V107 -> 3.1817882 | J17: ='Previous History'!W107 -> 0.013755272 | K17: ='Previous History'!T26 -> 494.51438 | L17: ='Previous History'!U26 -> 0.02237305 | M17: ='Previous History'!W26 -> 3.1765213 | N17: ='Previous History'!X26 -> 0.013732014 | O17: =Report!L28 -> 494.53587 | P17: =Report!M28 -> 0.029828297 | Q17: =Report!O28 -> 3.1675614 | R17: =Report!P28 -> 0.013693219 | S17: =Report!D28 -> 494.54123 | T17: =Report!E28 -> 0.031708301 | U17: =Report!G28 -> 3.1743629 | V17: =Report!H28 -> 0.013741586 | W17: =Report!AI28 -> 494.473 | X17: =Report!AJ28 -> 0.364 | Y17: =Report!AL28 -> 3.173 | Z17: =Report!AM28 -> 0.019 | AA17: =Report!AQ28 -> 494.43126 | AB17: =Report!AR28 -> 0.024043378 | AC17: =Report!AT28 -> 3.1989651 | AD17: =Report!AU28 -> 0.018855831
B18: B6 | C18: ='Previous History'!J82 -> 593.52154 | D18: ='Previous History'!K82 -> 0.030990853 | E18: ='Previous History'!M82 -> 3.5496697 | F18: ='Previous History'!N82 -> 0.01534567 | G18: ='Previous History'!S108 -> 593.52554 | H18: ='Previous History'!T108 -> 0.03098935 | I18: ='Previous History'!V108 -> 3.5435065 | J18: ='Previous History'!W108 -> 0.015319026 | K18: ='Previous History'!T27 -> 594.14458 | L18: ='Previous History'!U27 -> 0.12517757 | M18: ='Previous History'!W27 -> 3.5335417 | N18: ='Previous History'!X27 -> 0.015275654 | O18: =Report!L29 -> 593.62028 | P18: =Report!M29 -> 0.035740115 | Q18: =Report!O29 -> 3.5303874 | R18: =Report!P29 -> 0.015261709 | S18: =Report!D29 -> 593.59611 | T18: =Report!E29 -> 0.037780852 | U18: =Report!G29 -> 3.5374895 | V18: =Report!H29 -> 0.015313651 | W18: =Report!AI29 -> 593.512 | X18: =Report!AJ29 -> 0.028 | Y18: =Report!AL29 -> 3.535 | Z18: =Report!AM29 -> 0.021 | AA18: =Report!AQ29 -> 594.85153 | AB18: =Report!AR29 -> 0.028354887 | AC18: =Report!AT29 -> 3.5530616 | AD18: =Report!AU29 -> 0.020945548
B19: B7 | C19: ='Previous History'!J83 -> 691.35529 | D19: ='Previous History'!K83 -> 0.036026377 | E19: ='Previous History'!M83 -> 3.9065458 | F19: ='Previous History'!N83 -> 0.016888491 | G19: ='Previous History'!S109 -> 691.35429 | H19: ='Previous History'!T109 -> 0.036024535 | I19: ='Previous History'!V109 -> 3.8996025 | J19: ='Previous History'!W109 -> 0.016858474 | K19: ='Previous History'!T28 -> 691.38737 | L19: ='Previous History'!U28 -> 0.030514135 | M19: ='Previous History'!W28 -> 3.8930622 | N19: ='Previous History'!X28 -> 0.016829566 | O19: =Report!L30 -> 691.43446 | P19: =Report!M30 -> 0.041582222 | Q19: =Report!O30 -> 3.8822528 | R19: =Report!P30 -> 0.016782818 | S19: =Report!D30 -> 691.43474 | T19: =Report!E30 -> 0.043793554 | U19: =Report!G30 -> 3.8900894 | V19: =Report!H30 -> 0.016840154 | W19: =Report!AI30 -> 691.343 | X19: =Report!AJ30 -> 0.033 | Y19: =Report!AL30 -> 3.893 | Z19: =Report!AM30 -> 0.023 | AA19: =Report!AQ30 -> 691.30087 | AB19: =Report!AR30 -> 0.032572905 | AC19: =Report!AT30 -> 3.9212505 | AD19: =Report!AU30 -> 0.023114013
B20: B8 | C20: ='Previous History'!J84 -> 789.14603 | D20: ='Previous History'!K84 -> 0.041051582 | E20: ='Previous History'!M84 -> 4.2106495 | F20: ='Previous History'!N84 -> 0.018203169 | G20: ='Previous History'!S110 -> 789.14203 | H20: ='Previous History'!T110 -> 0.041049472 | I20: ='Previous History'!V110 -> 4.2027261 | J20: ='Previous History'!W110 -> 0.018168916 | K20: ='Previous History'!T29 -> 789.17826 | L20: ='Previous History'!U29 -> 0.034488312 | M20: ='Previous History'!W29 -> 4.1957495 | N20: ='Previous History'!X29 -> 0.018138065 | O20: =Report!L31 -> 789.23464 | P20: =Report!M31 -> 0.047423931 | Q20: =Report!O31 -> 4.1843013 | R20: =Report!P31 -> 0.018088575 | S20: =Report!D31 -> 789.22937 | T20: =Report!E31 -> 0.049780146 | U20: =Report!G31 -> 4.1925208 | V20: =Report!H31 -> 0.018149511 | W20: =Report!AI31 -> 789.131 | X20: =Report!AJ31 -> 0.037 | Y20: =Report!AL31 -> 4.197 | Z20: =Report!AM31 -> 0.025 | AA20: =Report!AQ31 -> 789.07784 | AB20: =Report!AR31 -> 0.036778844 | AC20: =Report!AT31 -> 4.2255214 | AD20: =Report!AU31 -> 0.024909422
B21: B9 | C21: ='Previous History'!J85 -> 887.36284 | D21: ='Previous History'!K85 -> 0.046106048 | E21: ='Previous History'!M85 -> 4.5292938 | F21: ='Previous History'!N85 -> 0.019580709 | G21: ='Previous History'!S111 -> 887.36984 | H21: ='Previous History'!T111 -> 0.0461044 | I21: ='Previous History'!V111 -> 4.5205204 | J21: ='Previous History'!W111 -> 0.01954278 | K21: ='Previous History'!T30 -> 887.39622 | L21: ='Previous History'!U30 -> 0.038437384 | M21: ='Previous History'!W30 -> 4.5130276 | N21: ='Previous History'!X30 -> 0.019509642 | O21: =Report!L32 -> 887.4889 | P21: =Report!M32 -> 0.053296749 | Q21: =Report!O32 -> 4.5008786 | R21: =Report!P32 -> 0.019457139 | S21: =Report!D32 -> 887.49408 | T21: =Report!E32 -> 0.055815985 | U21: =Report!G32 -> 4.5095331 | V21: =Report!H32 -> 0.019521989 | W21: =Report!AI32 -> 887.363 | X21: =Report!AJ32 -> 0.041 | Y21: =Report!AL32 -> 4.515 | Z21: =Report!AM32 -> 0.027 | AA21: =Report!AQ32 -> 887.3028 | AB21: =Report!AR32 -> 0.041046636 | AC21: =Report!AT32 -> 4.5463784 | AD21: =Report!AU32 -> 0.026798687
B22: B10 | C22: ='Previous History'!J86 -> 984.77052 | D22: ='Previous History'!K86 -> 0.051119816 | E22: ='Previous History'!M86 -> 4.8375777 | F22: ='Previous History'!N86 -> 0.020913459 | G22: ='Previous History'!S112 -> 984.77752 | H22: ='Previous History'!T112 -> 0.051118057 | I22: ='Previous History'!V112 -> 4.8278862 | J22: ='Previous History'!W112 -> 0.020871562 | K22: ='Previous History'!T31 -> 984.81804 | L22: ='Previous History'!U31 -> 0.04252501 | M22: ='Previous History'!W31 -> 4.8219112 | N22: ='Previous History'!X31 -> 0.020844886 | O22: =Report!L33 -> 984.94202 | P22: =Report!M33 -> 0.059123218 | Q22: =Report!O33 -> 4.8071564 | R22: =Report!P33 -> 0.020781179 | S22: =Report!D33 -> 984.95064 | T22: =Report!E33 -> 0.061804451 | U22: =Report!G33 -> 4.8162648 | V22: =Report!H33 -> 0.02084997 | W22: =Report!AI33 -> 984.794 | X22: =Report!AJ33 -> 0.045 | Y22: =Report!AL33 -> 4.823 | Z22: =Report!AM33 -> 0.029 | AA22: =Report!AQ33 -> 984.77975 | AB22: =Report!AR33 -> 0.045246445 | AC22: =Report!AT33 -> 4.8225633 | AD22: =Report!AU33 -> 0.0285084
A23: Note
A24: 45805 | C24: ## | D24: No report for S21069 found | E24: ## | F24: All figures from report S2****
B26: b10
C28: L | D28: uL | E28: R | F28: uR
B29: 34971 | C29: =VLOOKUP($B$26,previous,2,FALSE()) -> 984.77052 | D29: =VLOOKUP($B$26,previous,3,FALSE()) -> 0.051119816 | E29: =VLOOKUP($B$26,previous,4,FALSE()) -> 4.8375777 | F29: =VLOOKUP($B$26,previous,5,FALSE()) -> 0.020913459
B30: 36749 | C30: =VLOOKUP($B$26,previous,6,FALSE()) -> 984.77752 | D30: =VLOOKUP($B$26,previous,7,FALSE()) -> 0.051118057 | E30: =VLOOKUP($B$26,previous,8,FALSE()) -> 4.8278862 | F30: =VLOOKUP($B$26,previous,9,FALSE()) -> 0.020871562
B31: 38408 | C31: =VLOOKUP($B$26,previous,10,FALSE()) -> 984.81804 | D31: =VLOOKUP($B$26,previous,11,FALSE()) -> 0.04252501 | E31: =VLOOKUP($B$26,previous,12,FALSE()) -> 4.8219112 | F31: =VLOOKUP($B$26,previous,13,FALSE()) -> 0.020844886
B32: 39997 | C32: =VLOOKUP($B$26,previous,14,FALSE()) -> 984.94202 | D32: =VLOOKUP($B$26,previous,15,FALSE()) -> 0.059123218 | E32: =VLOOKUP($B$26,previous,16,FALSE()) -> 4.8071564 | F32: =VLOOKUP($B$26,previous,17,FALSE()) -> 0.020781179
B33: 41921 | C33: =VLOOKUP($B$26,previous,18,FALSE()) -> 984.95064 | D33: =VLOOKUP($B$26,previous,19,FALSE()) -> 0.061804451 | E33: =VLOOKUP($B$26,previous,20,FALSE()) -> 4.8162648 | F33: =VLOOKUP($B$26,previous,21,FALSE()) -> 0.02084997
B34: =W1 -> 44146 | C34: =VLOOKUP($B$26,previous,22,FALSE()) -> 984.794 | D34: =VLOOKUP($B$26,previous,23,FALSE()) -> 0.045 | E34: =VLOOKUP($B$26,previous,24,FALSE()) -> 4.823 | F34: =VLOOKUP($B$26,previous,25,FALSE()) -> 0.029

Sheet Report
A1: checked by: | D1: humidity | E1: ='Room data logger'!C55 -> 43.073469 | F1: %RH
D2: temperature | E2: =H3 -> 19.485 | K2: 39997 | Z2: 41921 | AP2: 45793
G3: temperature | H3: =AVERAGE(Results!L12:L31) -> 19.485 | K3: S21740 | L3: 2009 | AH3: 09-10/11/2020
B5: dial code | C5: Tap | D5: Inductance | E5: Expanded | F5: Coverage | G5: Resistance | H5: Expanded | I5: Coverage | K5: Tap | L5: Inductance | M5: Expanded | N5: Coverage | O5: Resistance | P5: Expanded | Q5: Coverage | Z5: Tap | AA5: Inductance | AB5: Expanded | AC5: Coverage | AD5: Resistance | AE5: Expanded | AF5: Coverage
E6: uncertainty | F6: factor | H6: uncertainty | I6: factor | M6: uncertainty | N6: factor | P6: uncertainty | Q6: factor | AB6: uncertainty | AC6: factor | AE6: uncertainty | AF6: factor
D7: (mH) | E7: (mH) | G7: (W) | H7: (W) | L7: (mH) | M7: (mH) | O7: (W) | P7: (W) | AA7: (mH) | AB7: (mH) | AD7: (W) | AE7: (W) | AH7: Tap | AI7: Inductance (µH) | AJ7: Expanded Uncertainty (µH) | AK7: Coverage Factor | AL7: Resistance (Ω) | AM7: Expanded Uncertainty (Ω) | AN7: Coverage Factor | AR7: uncertainty | AS7: factor | AU7: uncertainty | AV7: factor
B8: A1 | C8: 1 | D8: =VLOOKUP(B8,Rangex,5,FALSE())*1000 -> 994.1995 | E8: =VLOOKUP($B8,ub_uncertainty,2,FALSE())*1000 -> 0.070354849 | F8: =VLOOKUP($B8,ub_uncertainty,3,FALSE()) -> 2.0689921 | G8: =VLOOKUP(B8,Rangex,7,FALSE()) -> 5.6914915 | H8: =VLOOKUP($B8,ub_uncertainty,4,FALSE()) -> 0.024639447 | I8: =VLOOKUP($B8,ub_uncertainty,5,FALSE()) -> 2.1611894 | K8: 1 | L8: 994.06462 | M8: 0.065681418 | N8: 2.0503423 | O8: 5.6775487 | P8: 0.024544537 | Q8: 2.1614365 | Z8: 1 | AA8: 994.06462 | AB8: 0.065681418 | AC8: 2.0503423 | AD8: 5.6775487 | AE8: 0.024544537 | AF8: 2.1614365 | AH8: 1 | AI8: 994.017 | AJ8: 0.063 | AK8: 2 | AL8: 5.686 | AM8: 0.034 | AN8: 2.1 | AP8: 1 | AQ8: (mH) | AR8: (mH) | AT8: (W) | AU8: (W)
B9: A2 | C9: 2 | D9: =VLOOKUP(B9,Rangex,5,FALSE())*1000 -> 1980.7775 | E9: =VLOOKUP($B9,ub_uncertainty,2,FALSE())*1000 -> 0.12681451 | F9: =VLOOKUP($B9,ub_uncertainty,3,FALSE()) -> 2.0918646 | G9: =VLOOKUP(B9,Rangex,7,FALSE()) -> 8.3824613 | H9: =VLOOKUP($B9,ub_uncertainty,4,FALSE()) -> 0.036289918 | I9: =VLOOKUP($B9,ub_uncertainty,5,FALSE()) -> 2.1611657 | K9: 2 | L9: 1980.5079 | M9: 0.12155553 | N9: 2.0650028 | O9: 8.3614742 | P9: 0.036146852 | Q9: 2.1614658 | Z9: 2 | AA9: 1980.5079 | AB9: 0.12155553 | AC9: 2.0650028 | AD9: 8.3614742 | AE9: 0.036146852 | AF9: 2.1614658 | AH9: 2 | AI9: 1980.52 | AJ9: 0.1 | AK9: 2 | AL9: 8.374 | AM9: 0.05 | AN9: 2.1 | AP9: 2 | AQ9: 993.86518 | AR9: 0.06325821 | AS9: 1.9889169 | AT9: 5.7357593 | AU9: 0.033901539 | AV9: 2.0825444
B10: A3 | C10: 3 | D10: =VLOOKUP(B10,Rangex,5,FALSE())*1000 -> 2969.7059 | E10: =VLOOKUP($B10,ub_uncertainty,2,FALSE())*1000 -> 0.18621611 | F10: =VLOOKUP($B10,ub_uncertainty,3,FALSE()) -> 2.1049841 | G10: =VLOOKUP(B10,Rangex,7,FALSE()) -> 10.661872 | H10: =VLOOKUP($B10,ub_uncertainty,4,FALSE()) -> 0.04615965 | I10: =VLOOKUP($B10,ub_uncertainty,5,FALSE()) -> 2.1611208 | K10: 3 | L10: 2969.2816 | M10: 0.17972598 | N10: 2.071429 | O10: 10.635116 | P10: 0.045975788 | Q10: 2.1614717 | Z10: 3 | AA10: 2969.2816 | AB10: 0.17972598 | AC10: 2.071429 | AD10: 10.635116 | AE10: 0.045975788 | AF10: 2.1614717 | AH10: 3 | AI10: 2969.42 | AJ10: 0.14 | AK10: 2 | AL10: 10.653 | AM10: 0.063 | AN10: 2.1 | AP10: 3 | AQ10: 1980.1783 | AR10: 0.098608217 | AS10: 2.0001778 | AT10: 8.4486407 | AU10: 0.049860012 | AV10: 2.0836311
B11: A4 | C11: 4 | D11: =VLOOKUP(B11,Rangex,5,FALSE())*1000 -> 3949.4225 | E11: =VLOOKUP($B11,ub_uncertainty,2,FALSE())*1000 -> 0.24566312 | F11: =VLOOKUP($B11,ub_uncertainty,3,FALSE()) -> 2.1113631 | G11: =VLOOKUP(B11,Rangex,7,FALSE()) -> 12.646962 | H11: =VLOOKUP($B11,ub_uncertainty,4,FALSE()) -> 0.054755825 | I11: =VLOOKUP($B11,ub_uncertainty,5,FALSE()) -> 2.1610729 | K11: 4 | L11: 3948.8537 | M11: 0.23784992 | N11: 2.0741145 | O11: 12.61519 | P11: 0.054535761 | Q11: 2.1614719 | Z11: 4 | AA11: 3948.8537 | AB11: 0.23784992 | AC11: 2.0741145 | AD11: 12.61519 | AE11: 0.054535761 | AF11: 2.1614719 | AH11: 4 | AI11: 3949.15 | AJ11: 0.18 | AK11: 2 | AL11: 12.638 | AM11: 0.075 | AN11: 2.1 | AP11: 4 | AQ11: 2968.8291 | AR11: 0.13834134 | AS11: 2.0100638 | AT11: 10.732791 | AU11: 0.063325694 | AV11: 2.0844034
B12: A5 | C12: 5 | D12: =VLOOKUP(B12,Rangex,5,FALSE())*1000 -> 4933.3499 | E12: =VLOOKUP($B12,ub_uncertainty,2,FALSE())*1000 -> 0.30556722 | F12: =VLOOKUP($B12,ub_uncertainty,3,FALSE()) -> 2.1150498 | G12: =VLOOKUP(B12,Rangex,7,FALSE()) -> 14.414977 | H12: =VLOOKUP($B12,ub_uncertainty,4,FALSE()) -> 0.062412783 | I12: =VLOOKUP($B12,ub_uncertainty,5,FALSE()) -> 2.1610229 | K12: 5 | L12: 4932.5965 | M12: 0.29641068 | N12: 2.0754801 | O12: 14.378433 | P12: 0.062158453 | Q12: 2.1614697 | Z12: 5 | AA12: 4932.5965 | AB12: 0.29641068 | AC12: 2.0754801 | AD12: 14.378433 | AE12: 0.062158453 | AF12: 2.1614697 | AH12: 5 | AI12: 4933.13 | AJ12: 0.22 | AK12: 2 | AL12: 14.408 | AM12: 0.085 | AN12: 2.1 | AP12: 5 | AQ12: 3948.3254 | AR12: 0.17909506 | AS12: 2.0155571 | AT12: 12.739136 | AU12: 0.075136262 | AV12: 2.0843526
B13: A6 | C13: 6 | D13: =VLOOKUP(B13,Rangex,5,FALSE())*1000 -> 5915.9671 | E13: =VLOOKUP($B13,ub_uncertainty,2,FALSE())*1000 -> 0.36551399 | F13: =VLOOKUP($B13,ub_uncertainty,3,FALSE()) -> 2.1173334 | G13: =VLOOKUP(B13,Rangex,7,FALSE()) -> 16.100456 | H13: =VLOOKUP($B13,ub_uncertainty,4,FALSE()) -> 0.069712738 | I13: =VLOOKUP($B13,ub_uncertainty,5,FALSE()) -> 2.1609762 | K13: 6 | L13: 5915.0491 | M13: 0.35499064 | N13: 2.0762586 | O13: 16.05883 | P13: 0.069423052 | Q13: 2.1614669 | Z13: 6 | AA13: 5915.0491 | AB13: 0.35499064 | AC13: 2.0762586 | AD13: 16.05883 | AE13: 0.069423052 | AF13: 2.1614669 | AH13: 6 | AI13: 5915.88 | AJ13: 0.26 | AK13: 2 | AL13: 16.09 | AM13: 0.1 | AN13: 2.1 | AP13: 6 | AQ13: 4932.0819 | AR13: 0.22055479 | AS13: 2.0188846 | AT13: 14.52553 | AU13: 0.085657789 | AV13: 2.0843071
B14: A7 | C14: 7 | D14: =VLOOKUP(B14,Rangex,5,FALSE())*1000 -> 6892.8931 | E14: =VLOOKUP($B14,ub_uncertainty,2,FALSE())*1000 -> 0.42518958 | F14: =VLOOKUP($B14,ub_uncertainty,3,FALSE()) -> 2.1188414 | G14: =VLOOKUP(B14,Rangex,7,FALSE()) -> 17.743072 | H14: =VLOOKUP($B14,ub_uncertainty,4,FALSE()) -> 0.076827317 | I14: =VLOOKUP($B14,ub_uncertainty,5,FALSE()) -> 2.1609343 | K14: 7 | L14: 6891.8207 | M14: 0.41328669 | N14: 2.0767416 | O14: 17.696425 | P14: 0.076502643 | Q14: 2.161464 | Z14: 7 | AA14: 6891.8207 | AB14: 0.41328669 | AC14: 2.0767416 | AD14: 17.696425 | AE14: 0.076502643 | AF14: 2.161464 | AH14: 7 | AI14: 6892.98 | AJ14: 0.3 | AK14: 2 | AL14: 17.74 | AM14: 0.1 | AN14: 2.1 | AP14: 7 | AQ14: 5914.5845 | AR14: 0.2622122 | AS14: 2.0210773 | AT14: 16.217946 | AU14: 0.095650589 | AV14: 2.0846631
B15: A8 | C15: 8 | D15: =VLOOKUP(B15,Rangex,5,FALSE())*1000 -> 7865.3283 | E15: =VLOOKUP($B15,ub_uncertainty,2,FALSE())*1000 -> 0.48460715 | F15: =VLOOKUP($B15,ub_uncertainty,3,FALSE()) -> 2.1199614 | G15: =VLOOKUP(B15,Rangex,7,FALSE()) -> 19.257578 | H15: =VLOOKUP($B15,ub_uncertainty,4,FALSE()) -> 0.08338761 | I15: =VLOOKUP($B15,ub_uncertainty,5,FALSE()) -> 2.1608919 | K15: 8 | L15: 7864.1515 | M15: 0.47134832 | N15: 2.0770672 | O15: 19.206342 | P15: 0.083030327 | Q15: 2.1614607 | Z15: 8 | AA15: 7864.1515 | AB15: 0.47134832 | AC15: 2.0770672 | AD15: 19.206342 | AE15: 0.083030327 | AF15: 2.1614607 | AH15: 8 | AI15: 7865.64 | AJ15: 0.35 | AK15: 2 | AL15: 19.25 | AM15: 0.11 | AN15: 2.1 | AP15: 8 | AQ15: 6891.3862 | AR15: 0.30385653 | AS15: 2.0225241 | AT15: 17.870752 | AU15: 0.10540082 | AV15: 2.0847608
B16: A9 | C16: 9 | D16: =VLOOKUP(B16,Rangex,5,FALSE())*1000 -> 8834.5327 | E16: =VLOOKUP($B16,ub_uncertainty,2,FALSE())*1000 -> 0.54384988 | F16: =VLOOKUP($B16,ub_uncertainty,3,FALSE()) -> 2.1208049 | G16: =VLOOKUP(B16,Rangex,7,FALSE()) -> 20.713051 | H16: =VLOOKUP($B16,ub_uncertainty,4,FALSE()) -> 0.089692541 | I16: =VLOOKUP($B16,ub_uncertainty,5,FALSE()) -> 2.1608513 | K16: 9 | L16: 8833.2017 | M16: 0.52923558 | N16: 2.077297 | O16: 20.657266 | P16: 0.089303007 | Q16: 2.1614574 | Z16: 9 | AA16: 8833.2017 | AB16: 0.52923558 | AC16: 2.077297 | AD16: 20.657266 | AE16: 0.089303007 | AF16: 2.1614574 | AH16: 9 | AI16: 8835.46 | AJ16: 0.39 | AK16: 2 | AL16: 20.71 | AM16: 0.12 | AN16: 2.1 | AP16: 9 | AQ16: 7863.7411 | AR16: 0.34541627 | AS16: 2.0235577 | AT16: 19.401632 | AU16: 0.11441635 | AV16: 2.084676
